2022-01-07 12:06:14,840 - root - INFO - InfiniemBot Iniciado...
2022-01-07 12:06:14,844 - apscheduler.scheduler - INFO - Scheduler started
2022-01-07 12:06:35,776 - root - INFO - chat_id : 1211957358 and firstname : Max lastname : None  username None
2022-01-07 12:06:59,882 - __main__ - WARNING - [UPDATE] "{'message': {'chat': {'type': 'private', 'first_name': 'Max', 'id': 1211957358}, 'photo': [], 'entities': [{'offset': 0, 'type': 'bot_command', 'length': 6}], 'group_chat_created': False, 'delete_chat_photo': False, 'text': '/ayuda', 'message_id': 208, 'channel_chat_created': False, 'supergroup_chat_created': False, 'new_chat_members': [], 'date': 1641568019, 'new_chat_photo': [], 'caption_entities': [], 'from': {'language_code': 'en', 'id': 1211957358, 'first_name': 'Max', 'is_bot': False}}, 'update_id': 197674620}" causa del error "Object of type function is not JSON serializable"
2022-01-07 12:07:24,002 - __main__ - WARNING - [UPDATE] "{'message': {'chat': {'type': 'private', 'first_name': 'Max', 'id': 1211957358}, 'photo': [], 'entities': [{'offset': 0, 'type': 'bot_command', 'length': 6}], 'group_chat_created': False, 'delete_chat_photo': False, 'text': '/ayuda', 'message_id': 209, 'channel_chat_created': False, 'supergroup_chat_created': False, 'new_chat_members': [], 'date': 1641568043, 'new_chat_photo': [], 'caption_entities': [], 'from': {'language_code': 'en', 'id': 1211957358, 'first_name': 'Max', 'is_bot': False}}, 'update_id': 197674621}" causa del error "Object of type function is not JSON serializable"
2022-01-07 12:07:28,312 - __main__ - WARNING - [UPDATE] "{'message': {'chat': {'type': 'private', 'first_name': 'Max', 'id': 1211957358}, 'photo': [], 'entities': [{'offset': 0, 'type': 'bot_command', 'length': 6}], 'group_chat_created': False, 'delete_chat_photo': False, 'text': '/ayuda', 'message_id': 210, 'channel_chat_created': False, 'supergroup_chat_created': False, 'new_chat_members': [], 'date': 1641568048, 'new_chat_photo': [], 'caption_entities': [], 'from': {'language_code': 'en', 'id': 1211957358, 'first_name': 'Max', 'is_bot': False}}, 'update_id': 197674622}" causa del error "Object of type function is not JSON serializable"
2022-01-07 12:07:39,510 - telegram.ext.updater - INFO - Received signal 2 (SIGINT), stopping...
2022-01-07 12:07:39,510 - apscheduler.scheduler - INFO - Scheduler has been shut down
2022-01-07 12:07:43,972 - telegram.ext.updater - WARNING - Exiting immediately!
2022-01-07 12:07:45,275 - root - INFO - InfiniemBot Iniciado...
2022-01-07 12:07:45,277 - apscheduler.scheduler - INFO - Scheduler started
2022-01-07 12:07:54,161 - telegram.ext.updater - INFO - Received signal 2 (SIGINT), stopping...
2022-01-07 12:07:54,161 - apscheduler.scheduler - INFO - Scheduler has been shut down
2022-01-07 12:07:54,451 - telegram.ext.updater - WARNING - Exiting immediately!
2022-01-07 12:08:16,040 - root - INFO - InfiniemBot Iniciado...
2022-01-07 12:08:16,042 - apscheduler.scheduler - INFO - Scheduler started
2022-01-07 12:09:53,118 - telegram.ext.updater - INFO - Received signal 2 (SIGINT), stopping...
2022-01-07 12:09:53,119 - apscheduler.scheduler - INFO - Scheduler has been shut down
2022-01-07 12:09:53,814 - telegram.ext.updater - WARNING - Exiting immediately!
2022-01-07 12:09:57,929 - root - INFO - InfiniemBot Iniciado...
2022-01-07 12:09:57,930 - apscheduler.scheduler - INFO - Scheduler started
2022-01-07 12:10:43,753 - telegram.ext.updater - INFO - Received signal 2 (SIGINT), stopping...
2022-01-07 12:10:43,753 - apscheduler.scheduler - INFO - Scheduler has been shut down
2022-01-07 12:10:44,023 - telegram.ext.updater - WARNING - Exiting immediately!
2022-01-07 12:10:45,633 - root - INFO - InfiniemBot Iniciado...
2022-01-07 12:10:45,635 - apscheduler.scheduler - INFO - Scheduler started
2022-01-07 12:10:49,356 - __main__ - WARNING - [UPDATE] "{'message': {'group_chat_created': False, 'caption_entities': [], 'message_id': 217, 'supergroup_chat_created': False, 'chat': {'type': 'private', 'id': 1211957358, 'first_name': 'Max'}, 'entities': [{'offset': 0, 'length': 6, 'type': 'bot_command'}], 'photo': [], 'new_chat_members': [], 'delete_chat_photo': False, 'channel_chat_created': False, 'new_chat_photo': [], 'date': 1641568248, 'text': '/ayuda', 'from': {'id': 1211957358, 'language_code': 'en', 'first_name': 'Max', 'is_bot': False}}, 'update_id': 197674626}" causa del error "Unsupported parse_mode"
2022-01-07 12:10:54,545 - __main__ - WARNING - [UPDATE] "{'message': {'group_chat_created': False, 'caption_entities': [], 'message_id': 218, 'supergroup_chat_created': False, 'chat': {'type': 'private', 'id': 1211957358, 'first_name': 'Max'}, 'entities': [{'offset': 0, 'length': 6, 'type': 'bot_command'}], 'photo': [], 'new_chat_members': [], 'delete_chat_photo': False, 'channel_chat_created': False, 'new_chat_photo': [], 'date': 1641568254, 'text': '/ayuda', 'from': {'id': 1211957358, 'language_code': 'en', 'first_name': 'Max', 'is_bot': False}}, 'update_id': 197674627}" causa del error "Unsupported parse_mode"
2022-01-07 12:11:26,689 - telegram.ext.updater - INFO - Received signal 2 (SIGINT), stopping...
2022-01-07 12:11:26,690 - apscheduler.scheduler - INFO - Scheduler has been shut down
2022-01-07 12:11:26,960 - telegram.ext.updater - WARNING - Exiting immediately!
2022-01-07 12:12:18,613 - root - INFO - InfiniemBot Iniciado...
2022-01-07 12:12:18,615 - apscheduler.scheduler - INFO - Scheduler started
2022-01-07 12:12:24,352 - __main__ - WARNING - [UPDATE] "{'message': {'new_chat_members': [], 'date': 1641568342, 'supergroup_chat_created': False, 'chat': {'first_name': 'Max', 'type': 'private', 'id': 1211957358}, 'group_chat_created': False, 'delete_chat_photo': False, 'caption_entities': [], 'message_id': 219, 'entities': [{'type': 'bot_command', 'offset': 0, 'length': 6}], 'channel_chat_created': False, 'new_chat_photo': [], 'photo': [], 'text': '/ayuda', 'from': {'is_bot': False, 'id': 1211957358, 'language_code': 'en', 'first_name': 'Max'}}, 'update_id': 197674628}" causa del error "Unsupported parse_mode"
2022-01-07 12:12:26,435 - __main__ - WARNING - [UPDATE] "{'message': {'new_chat_members': [], 'date': 1641568346, 'supergroup_chat_created': False, 'chat': {'first_name': 'Max', 'type': 'private', 'id': 1211957358}, 'group_chat_created': False, 'delete_chat_photo': False, 'caption_entities': [], 'message_id': 220, 'entities': [{'type': 'bot_command', 'offset': 0, 'length': 6}], 'channel_chat_created': False, 'new_chat_photo': [], 'photo': [], 'text': '/ayuda', 'from': {'is_bot': False, 'id': 1211957358, 'language_code': 'en', 'first_name': 'Max'}}, 'update_id': 197674629}" causa del error "Unsupported parse_mode"
2022-01-07 12:12:29,898 - telegram.ext.updater - INFO - Received signal 2 (SIGINT), stopping...
2022-01-07 12:12:29,898 - apscheduler.scheduler - INFO - Scheduler has been shut down
2022-01-07 12:12:30,179 - telegram.ext.updater - WARNING - Exiting immediately!
2022-01-07 12:12:44,049 - root - INFO - InfiniemBot Iniciado...
2022-01-07 12:12:44,051 - apscheduler.scheduler - INFO - Scheduler started
2022-01-07 12:12:47,392 - __main__ - WARNING - [UPDATE] "{'update_id': 197674630, 'message': {'photo': [], 'caption_entities': [], 'new_chat_photo': [], 'date': 1641568367, 'channel_chat_created': False, 'supergroup_chat_created': False, 'entities': [{'length': 6, 'offset': 0, 'type': 'bot_command'}], 'new_chat_members': [], 'group_chat_created': False, 'message_id': 221, 'chat': {'first_name': 'Max', 'type': 'private', 'id': 1211957358}, 'delete_chat_photo': False, 'text': '/ayuda', 'from': {'language_code': 'en', 'first_name': 'Max', 'is_bot': False, 'id': 1211957358}}}" causa del error "can only concatenate str (not "list") to str"
2022-01-07 12:12:50,264 - __main__ - WARNING - [UPDATE] "{'update_id': 197674631, 'message': {'photo': [], 'caption_entities': [], 'new_chat_photo': [], 'date': 1641568370, 'channel_chat_created': False, 'supergroup_chat_created': False, 'entities': [{'length': 6, 'offset': 0, 'type': 'bot_command'}], 'new_chat_members': [], 'group_chat_created': False, 'message_id': 222, 'chat': {'first_name': 'Max', 'type': 'private', 'id': 1211957358}, 'delete_chat_photo': False, 'text': '/ayuda', 'from': {'language_code': 'en', 'first_name': 'Max', 'is_bot': False, 'id': 1211957358}}}" causa del error "can only concatenate str (not "list") to str"
2022-01-07 12:13:20,627 - telegram.ext.updater - INFO - Received signal 2 (SIGINT), stopping...
2022-01-07 12:13:20,627 - apscheduler.scheduler - INFO - Scheduler has been shut down
2022-01-07 12:25:03,379 - root - INFO - InfiniemBot Iniciado...
2022-01-07 12:25:03,381 - apscheduler.scheduler - INFO - Scheduler started
2022-01-07 12:25:05,090 - root - INFO - chat_id : 1211957358 and firstname : Max lastname : None  username None
2022-01-07 12:25:06,349 - root - INFO - chat_id : 1211957358 and firstname : Max lastname : None  username None
2022-01-07 12:25:12,833 - __main__ - INFO - Usuario Max cancel√≥ la conversacion.
2022-01-07 12:36:52,862 - telegram.ext.updater - INFO - Received signal 2 (SIGINT), stopping...
2022-01-07 12:36:52,862 - apscheduler.scheduler - INFO - Scheduler has been shut down
2022-01-07 12:36:53,277 - telegram.ext.updater - WARNING - Exiting immediately!
2022-01-07 12:44:55,342 - root - INFO - InfiniemBot Iniciado...
2022-01-07 12:44:55,347 - apscheduler.scheduler - INFO - Scheduler started
2022-01-07 12:44:56,992 - root - INFO - chat_id : 1211957358 and firstname : Max lastname : None  username None
2022-01-07 12:47:07,130 - telegram.ext.updater - INFO - Received signal 2 (SIGINT), stopping...
2022-01-07 12:47:07,130 - apscheduler.scheduler - INFO - Scheduler has been shut down
2022-01-07 12:47:07,770 - telegram.ext.updater - WARNING - Exiting immediately!
2022-01-07 12:54:16,291 - root - INFO - InfiniemBot Iniciado...
2022-01-07 12:55:06,368 - root - INFO - InfiniemBot Iniciado...
2022-01-07 12:55:06,372 - apscheduler.scheduler - INFO - Scheduler started
2022-01-07 12:55:08,237 - root - INFO - chat_id : 1211957358 and firstname : Max lastname : None  username None
2022-01-07 12:55:09,158 - root - INFO - chat_id : 1211957358 and firstname : Max lastname : None  username None
2022-01-07 12:55:11,447 - __main__ - INFO - Usuario Max consume el servicio /hernan
2022-01-07 12:55:25,147 - __main__ - INFO - Usuario Max consume el servicio /hernan
2022-01-07 12:56:28,409 - telegram.ext.updater - INFO - Received signal 2 (SIGINT), stopping...
2022-01-07 12:56:28,409 - apscheduler.scheduler - INFO - Scheduler has been shut down
2022-01-07 12:56:30,881 - telegram.ext.updater - WARNING - Exiting immediately!
2022-01-07 12:56:32,884 - root - INFO - InfiniemBot Iniciado...
2022-01-07 12:56:42,330 - root - INFO - InfiniemBot Iniciado...
2022-01-07 12:56:42,332 - apscheduler.scheduler - INFO - Scheduler started
2022-01-07 12:57:55,963 - telegram.ext.updater - ERROR - Error while getting Updates: Conflict: terminated by other getUpdates request; make sure that only one bot instance is running
2022-01-07 12:57:55,963 - __main__ - WARNING - [UPDATE] "None" causa del error "Conflict: terminated by other getUpdates request; make sure that only one bot instance is running"
2022-01-07 13:12:32,100 - telegram.ext.updater - INFO - Received signal 2 (SIGINT), stopping...
2022-01-07 13:12:32,100 - apscheduler.scheduler - INFO - Scheduler has been shut down
2022-01-07 13:12:32,410 - telegram.ext.updater - WARNING - Exiting immediately!
2022-01-07 13:12:34,270 - root - INFO - InfiniemBot Iniciado...
2022-01-07 13:12:34,272 - apscheduler.scheduler - INFO - Scheduler started
2022-01-07 13:15:27,138 - telegram.ext.updater - INFO - Received signal 2 (SIGINT), stopping...
2022-01-07 13:15:27,138 - apscheduler.scheduler - INFO - Scheduler has been shut down
2022-01-07 13:15:28,174 - telegram.ext.updater - WARNING - Exiting immediately!
2022-01-07 13:15:29,766 - root - INFO - InfiniemBot Iniciado...
2022-01-07 13:15:29,768 - apscheduler.scheduler - INFO - Scheduler started
2022-01-07 13:15:35,358 - __main__ - WARNING - [UPDATE] "{'update_id': 197674641, 'edited_message': {'entities': [{'length': 9, 'offset': 0, 'type': 'bot_command'}], 'new_chat_photo': [], 'message_id': 241, 'photo': [], 'supergroup_chat_created': False, 'text': '/sensores\xa0üå°', 'caption_entities': [], 'new_chat_members': [], 'delete_chat_photo': False, 'group_chat_created': False, 'date': 1641571063, 'chat': {'type': 'private', 'first_name': 'Max', 'id': 1211957358}, 'edit_date': 1641572135, 'channel_chat_created': False, 'from': {'first_name': 'Max', 'language_code': 'en', 'id': 1211957358, 'is_bot': False}}}" causa del error "'NoneType' object has no attribute 'chat_id'"
2022-01-07 13:15:42,458 - __main__ - INFO - [UPDATE] Usuario Max consume el servicio /hernan
2022-01-07 13:19:07,329 - root - INFO - [NEW ACCESS] chat_id : 1211957358 - firstname : Max - lastname : None - username None
2022-01-07 13:19:18,114 - __main__ - INFO - [UPDATE] Usuario Max consume el servicio /hernan
2022-01-07 13:28:05,123 - telegram.ext.updater - ERROR - Error while getting Updates: Conflict: terminated by other getUpdates request; make sure that only one bot instance is running
2022-01-07 13:28:05,123 - __main__ - WARNING - [UPDATE] "None" causa del error "Conflict: terminated by other getUpdates request; make sure that only one bot instance is running"
2022-01-07 13:37:12,357 - telegram.ext.updater - INFO - Received signal 2 (SIGINT), stopping...
2022-01-07 13:37:12,358 - apscheduler.scheduler - INFO - Scheduler has been shut down
2022-01-07 13:37:12,612 - telegram.ext.updater - WARNING - Exiting immediately!
2022-01-07 13:37:14,702 - root - INFO - InfiniemBot Iniciado...
2022-01-07 13:37:14,704 - apscheduler.scheduler - INFO - Scheduler started
2022-01-07 13:37:19,178 - root - INFO - [NEW ACCESS] chat_id : 1211957358 - firstname : Max - lastname : None - username None
2022-01-07 13:37:21,815 - __main__ - INFO - [UPDATE] Usuario Max consume el servicio /buscar üîé
2022-01-07 13:37:57,987 - telegram.ext.updater - INFO - Received signal 2 (SIGINT), stopping...
2022-01-07 13:37:57,987 - apscheduler.scheduler - INFO - Scheduler has been shut down
2022-01-07 13:37:58,419 - telegram.ext.updater - WARNING - Exiting immediately!
2022-01-07 13:44:12,426 - root - INFO - InfiniemBot Iniciado...
2022-01-07 13:44:12,428 - apscheduler.scheduler - INFO - Scheduler started
2022-01-07 13:44:19,918 - root - INFO - [NEW ACCESS] chat_id : 1211957358 - firstname : Max - lastname : None - username None
2022-01-07 13:44:22,979 - __main__ - INFO - [UPDATE] Usuario Max consume el servicio /buscar üîé
2022-01-07 13:50:20,100 - telegram.ext.updater - INFO - Received signal 2 (SIGINT), stopping...
2022-01-07 13:50:20,100 - apscheduler.scheduler - INFO - Scheduler has been shut down
2022-01-07 13:50:20,363 - telegram.ext.updater - WARNING - Exiting immediately!
2022-01-07 13:50:23,510 - root - INFO - InfiniemBot Iniciado...
2022-01-07 13:50:23,513 - apscheduler.scheduler - INFO - Scheduler started
2022-01-07 13:50:26,034 - __main__ - INFO - [UPDATE] Usuario Max consume el servicio /buscar
2022-01-07 13:52:03,683 - __main__ - INFO - [UPDATE] Usuario Max consume el servicio /buscar
2022-01-07 13:54:41,809 - telegram.ext.updater - INFO - Received signal 2 (SIGINT), stopping...
2022-01-07 13:54:41,809 - apscheduler.scheduler - INFO - Scheduler has been shut down
2022-01-07 13:54:42,065 - telegram.ext.updater - WARNING - Exiting immediately!
2022-01-07 13:54:43,763 - root - INFO - InfiniemBot Iniciado...
2022-01-07 13:54:43,766 - apscheduler.scheduler - INFO - Scheduler started
2022-01-07 13:54:56,339 - __main__ - INFO - [UPDATE] Usuario Max consume el servicio /buscar
2022-01-07 13:54:56,340 - __main__ - WARNING - [UPDATE] "{'update_id': 197674657, 'message': {'caption_entities': [], 'delete_chat_photo': False, 'channel_chat_created': False, 'date': 1641574496, 'chat': {'first_name': 'Max', 'id': 1211957358, 'type': 'private'}, 'entities': [{'length': 7, 'offset': 0, 'type': 'bot_command'}], 'new_chat_members': [], 'photo': [], 'group_chat_created': False, 'text': '/buscar', 'message_id': 269, 'new_chat_photo': [], 'supergroup_chat_created': False, 'from': {'language_code': 'en', 'first_name': 'Max', 'id': 1211957358, 'is_bot': False}}}" causa del error "reply_text() got multiple values for argument 'text'"
2022-01-07 13:55:46,738 - telegram.ext.updater - INFO - Received signal 2 (SIGINT), stopping...
2022-01-07 13:55:46,739 - apscheduler.scheduler - INFO - Scheduler has been shut down
2022-01-07 13:55:47,058 - telegram.ext.updater - WARNING - Exiting immediately!
2022-01-07 13:55:51,307 - root - INFO - InfiniemBot Iniciado...
2022-01-07 13:55:51,308 - apscheduler.scheduler - INFO - Scheduler started
2022-01-07 13:55:53,693 - __main__ - INFO - [UPDATE] Usuario Max consume el servicio /buscar
2022-01-07 13:56:09,378 - telegram.ext.updater - INFO - Received signal 2 (SIGINT), stopping...
2022-01-07 13:56:09,378 - apscheduler.scheduler - INFO - Scheduler has been shut down
2022-01-07 13:56:09,850 - telegram.ext.updater - WARNING - Exiting immediately!
2022-01-07 13:56:11,627 - root - INFO - InfiniemBot Iniciado...
2022-01-07 13:56:11,628 - apscheduler.scheduler - INFO - Scheduler started
2022-01-07 13:56:14,815 - __main__ - INFO - [UPDATE] Usuario Max consume el servicio /buscar
2022-01-07 13:56:14,816 - __main__ - WARNING - [UPDATE] "{'message': {'caption_entities': [], 'message_id': 273, 'chat': {'id': 1211957358, 'type': 'private', 'first_name': 'Max'}, 'channel_chat_created': False, 'group_chat_created': False, 'entities': [{'type': 'bot_command', 'offset': 0, 'length': 7}], 'new_chat_members': [], 'new_chat_photo': [], 'supergroup_chat_created': False, 'photo': [], 'text': '/buscar', 'delete_chat_photo': False, 'date': 1641574574, 'from': {'first_name': 'Max', 'language_code': 'en', 'is_bot': False, 'id': 1211957358}}, 'update_id': 197674661}" causa del error "Object of type _Helper is not JSON serializable"
2022-01-07 13:56:16,625 - __main__ - INFO - [UPDATE] Usuario Max consume el servicio /buscar
2022-01-07 13:56:16,626 - __main__ - WARNING - [UPDATE] "{'message': {'caption_entities': [], 'message_id': 274, 'chat': {'id': 1211957358, 'type': 'private', 'first_name': 'Max'}, 'channel_chat_created': False, 'group_chat_created': False, 'entities': [{'type': 'bot_command', 'offset': 0, 'length': 7}], 'new_chat_members': [], 'new_chat_photo': [], 'supergroup_chat_created': False, 'photo': [], 'text': '/buscar', 'delete_chat_photo': False, 'date': 1641574576, 'from': {'first_name': 'Max', 'language_code': 'en', 'is_bot': False, 'id': 1211957358}}, 'update_id': 197674662}" causa del error "Object of type _Helper is not JSON serializable"
2022-01-07 13:56:22,005 - __main__ - INFO - [UPDATE] Usuario Max consume el servicio /buscar
2022-01-07 13:56:22,005 - __main__ - WARNING - [UPDATE] "{'message': {'caption_entities': [], 'message_id': 276, 'chat': {'id': 1211957358, 'type': 'private', 'first_name': 'Max'}, 'channel_chat_created': False, 'group_chat_created': False, 'entities': [{'type': 'bot_command', 'offset': 0, 'length': 7}], 'new_chat_members': [], 'new_chat_photo': [], 'supergroup_chat_created': False, 'photo': [], 'text': '/buscar', 'delete_chat_photo': False, 'date': 1641574581, 'from': {'first_name': 'Max', 'language_code': 'en', 'is_bot': False, 'id': 1211957358}}, 'update_id': 197674664}" causa del error "Object of type _Helper is not JSON serializable"
2022-01-07 13:56:27,875 - telegram.ext.updater - INFO - Received signal 2 (SIGINT), stopping...
2022-01-07 13:56:27,875 - apscheduler.scheduler - INFO - Scheduler has been shut down
2022-01-07 13:56:28,107 - telegram.ext.updater - WARNING - Exiting immediately!
2022-01-07 19:46:49,853 - root - INFO - InfiniemBot Iniciado...
2022-01-07 19:46:49,857 - apscheduler.scheduler - INFO - Scheduler started
2022-01-07 19:46:51,524 - __main__ - INFO - [UPDATE] Usuario Max consume el servicio /buscar üîé
2022-01-07 19:47:17,052 - root - INFO - [NEW ACCESS] chat_id : 1211957358 - firstname : Max - lastname : None - username None
2022-01-07 19:48:18,878 - telegram.ext.updater - INFO - Received signal 2 (SIGINT), stopping...
2022-01-07 19:48:18,878 - apscheduler.scheduler - INFO - Scheduler has been shut down
2022-01-07 19:48:19,465 - telegram.ext.updater - WARNING - Exiting immediately!
2022-01-07 19:48:21,215 - root - INFO - InfiniemBot Iniciado...
2022-01-07 19:48:21,220 - apscheduler.scheduler - INFO - Scheduler started
2022-01-07 20:05:39,731 - telegram.ext.updater - INFO - Received signal 2 (SIGINT), stopping...
2022-01-07 20:05:39,732 - apscheduler.scheduler - INFO - Scheduler has been shut down
2022-01-07 20:05:40,207 - telegram.ext.updater - WARNING - Exiting immediately!
2022-01-07 20:07:06,056 - root - INFO - InfiniemBot Iniciado...
2022-01-07 20:07:06,060 - apscheduler.scheduler - INFO - Scheduler started
2022-01-07 20:07:07,690 - __main__ - INFO - [UPDATE] Usuario Max consume el servicio /buscar üîé
2022-01-07 20:07:09,701 - __main__ - INFO - [UPDATE] Usuario Max consume el servicio /buscar üîé
2022-01-07 20:18:59,113 - telegram.ext.updater - ERROR - Error while getting Updates: Conflict: terminated by other getUpdates request; make sure that only one bot instance is running
2022-01-07 20:18:59,113 - __main__ - WARNING - [UPDATE] "None" causa del error "Conflict: terminated by other getUpdates request; make sure that only one bot instance is running"
2022-01-07 20:42:03,849 - telegram.ext.updater - INFO - Received signal 2 (SIGINT), stopping...
2022-01-07 20:42:03,851 - apscheduler.scheduler - INFO - Scheduler has been shut down
2022-01-07 20:42:11,689 - root - INFO - InfiniemBot Iniciado...
2022-01-07 20:42:11,696 - apscheduler.scheduler - INFO - Scheduler started
2022-01-07 20:43:28,381 - __main__ - INFO - [UPDATE] Usuario Max consume el servicio /buscar üîé
2022-01-07 21:02:14,635 - telegram.ext.updater - INFO - Received signal 2 (SIGINT), stopping...
2022-01-07 21:02:14,636 - apscheduler.scheduler - INFO - Scheduler has been shut down
2022-01-07 21:02:15,659 - telegram.ext.updater - WARNING - Exiting immediately!
2022-01-07 21:02:19,947 - root - INFO - InfiniemBot Iniciado...
2022-01-07 21:02:19,950 - apscheduler.scheduler - INFO - Scheduler started
2022-01-07 21:03:32,732 - __main__ - INFO - [UPDATE] Usuario Max cancel√≥ la conversacion.
2022-01-07 21:03:48,327 - root - INFO - [NEW ACCESS] chat_id : 1211957358 - firstname : Max - lastname : None - username None
2022-01-07 21:06:16,997 - telegram.ext.updater - INFO - Received signal 2 (SIGINT), stopping...
2022-01-07 21:06:16,998 - apscheduler.scheduler - INFO - Scheduler has been shut down
2022-01-07 21:06:17,688 - telegram.ext.updater - WARNING - Exiting immediately!
2022-01-07 21:06:19,376 - root - INFO - InfiniemBot Iniciado...
2022-01-07 21:06:19,379 - apscheduler.scheduler - INFO - Scheduler started
2022-01-07 21:06:34,923 - __main__ - INFO - [UPDATE] Usuario Max cancel√≥ la conversacion.
2022-01-07 21:17:17,824 - telegram.ext.updater - INFO - Received signal 2 (SIGINT), stopping...
2022-01-07 21:17:17,825 - apscheduler.scheduler - INFO - Scheduler has been shut down
2022-01-07 21:17:18,550 - telegram.ext.updater - WARNING - Exiting immediately!
2022-01-07 21:17:20,387 - root - INFO - InfiniemBot Iniciado...
2022-01-07 21:31:10,693 - root - INFO - InfiniemBot Iniciado...
2022-01-07 21:31:10,696 - apscheduler.scheduler - INFO - Scheduler started
2022-01-07 21:31:12,419 - root - INFO - [NEW ACCESS] chat_id : 1211957358 - firstname : Max - lastname : None - username None
2022-01-07 21:31:15,623 - __main__ - INFO - [UPDATE] Usuario Max consume el servicio /buscar üîé
2022-01-07 22:33:04,633 - telegram.vendor.ptb_urllib3.urllib3.connectionpool - WARNING - Retrying (Retry(total=2, connect=None, read=None, redirect=None)) after connection broken by 'NewConnectionError('<telegram.vendor.ptb_urllib3.urllib3.connection.VerifiedHTTPSConnection object at 0x7f56d82964f0>: Failed to establish a new connection: [Errno -3] Temporary failure in name resolution')': /bot5019690287:AAH9nfL4sWzLiF5Tuza3Jf_DuqiFJZo8qqI/getUpdates
2022-01-07 22:33:04,716 - telegram.vendor.ptb_urllib3.urllib3.connectionpool - WARNING - Retrying (Retry(total=1, connect=None, read=None, redirect=None)) after connection broken by 'NewConnectionError('<telegram.vendor.ptb_urllib3.urllib3.connection.VerifiedHTTPSConnection object at 0x7f56d8296310>: Failed to establish a new connection: [Errno -3] Temporary failure in name resolution')': /bot5019690287:AAH9nfL4sWzLiF5Tuza3Jf_DuqiFJZo8qqI/getUpdates
2022-01-07 22:33:04,765 - telegram.vendor.ptb_urllib3.urllib3.connectionpool - WARNING - Retrying (Retry(total=0, connect=None, read=None, redirect=None)) after connection broken by 'NewConnectionError('<telegram.vendor.ptb_urllib3.urllib3.connection.VerifiedHTTPSConnection object at 0x7f56d82968e0>: Failed to establish a new connection: [Errno -3] Temporary failure in name resolution')': /bot5019690287:AAH9nfL4sWzLiF5Tuza3Jf_DuqiFJZo8qqI/getUpdates
2022-01-07 22:33:04,814 - telegram.ext.updater - ERROR - Error while getting Updates: urllib3 HTTPError HTTPSConnectionPool(host='api.telegram.org', port=443): Max retries exceeded with url: /bot5019690287:AAH9nfL4sWzLiF5Tuza3Jf_DuqiFJZo8qqI/getUpdates (Caused by NewConnectionError('<telegram.vendor.ptb_urllib3.urllib3.connection.VerifiedHTTPSConnection object at 0x7f56d8296af0>: Failed to establish a new connection: [Errno -3] Temporary failure in name resolution'))
2022-01-07 22:33:04,816 - __main__ - WARNING - [UPDATE] "None" causa del error "urllib3 HTTPError HTTPSConnectionPool(host='api.telegram.org', port=443): Max retries exceeded with url: /bot5019690287:AAH9nfL4sWzLiF5Tuza3Jf_DuqiFJZo8qqI/getUpdates (Caused by NewConnectionError('<telegram.vendor.ptb_urllib3.urllib3.connection.VerifiedHTTPSConnection object at 0x7f56d8296af0>: Failed to establish a new connection: [Errno -3] Temporary failure in name resolution'))"
2022-01-07 22:33:05,823 - telegram.vendor.ptb_urllib3.urllib3.connectionpool - WARNING - Retrying (Retry(total=2, connect=None, read=None, redirect=None)) after connection broken by 'NewConnectionError('<telegram.vendor.ptb_urllib3.urllib3.connection.VerifiedHTTPSConnection object at 0x7f56d8287820>: Failed to establish a new connection: [Errno -3] Temporary failure in name resolution')': /bot5019690287:AAH9nfL4sWzLiF5Tuza3Jf_DuqiFJZo8qqI/getUpdates
2022-01-07 22:33:05,826 - telegram.vendor.ptb_urllib3.urllib3.connectionpool - WARNING - Retrying (Retry(total=1, connect=None, read=None, redirect=None)) after connection broken by 'NewConnectionError('<telegram.vendor.ptb_urllib3.urllib3.connection.VerifiedHTTPSConnection object at 0x7f56d8296280>: Failed to establish a new connection: [Errno -3] Temporary failure in name resolution')': /bot5019690287:AAH9nfL4sWzLiF5Tuza3Jf_DuqiFJZo8qqI/getUpdates
2022-01-07 22:33:05,829 - telegram.vendor.ptb_urllib3.urllib3.connectionpool - WARNING - Retrying (Retry(total=0, connect=None, read=None, redirect=None)) after connection broken by 'NewConnectionError('<telegram.vendor.ptb_urllib3.urllib3.connection.VerifiedHTTPSConnection object at 0x7f56d8296c40>: Failed to establish a new connection: [Errno -3] Temporary failure in name resolution')': /bot5019690287:AAH9nfL4sWzLiF5Tuza3Jf_DuqiFJZo8qqI/getUpdates
2022-01-07 22:33:05,835 - telegram.ext.updater - ERROR - Error while getting Updates: urllib3 HTTPError HTTPSConnectionPool(host='api.telegram.org', port=443): Max retries exceeded with url: /bot5019690287:AAH9nfL4sWzLiF5Tuza3Jf_DuqiFJZo8qqI/getUpdates (Caused by NewConnectionError('<telegram.vendor.ptb_urllib3.urllib3.connection.VerifiedHTTPSConnection object at 0x7f56d8296d90>: Failed to establish a new connection: [Errno -3] Temporary failure in name resolution'))
2022-01-07 22:33:05,837 - __main__ - WARNING - [UPDATE] "None" causa del error "urllib3 HTTPError HTTPSConnectionPool(host='api.telegram.org', port=443): Max retries exceeded with url: /bot5019690287:AAH9nfL4sWzLiF5Tuza3Jf_DuqiFJZo8qqI/getUpdates (Caused by NewConnectionError('<telegram.vendor.ptb_urllib3.urllib3.connection.VerifiedHTTPSConnection object at 0x7f56d8296d90>: Failed to establish a new connection: [Errno -3] Temporary failure in name resolution'))"
2022-01-07 22:33:07,340 - telegram.vendor.ptb_urllib3.urllib3.connectionpool - WARNING - Retrying (Retry(total=2, connect=None, read=None, redirect=None)) after connection broken by 'NewConnectionError('<telegram.vendor.ptb_urllib3.urllib3.connection.VerifiedHTTPSConnection object at 0x7f56d8296b50>: Failed to establish a new connection: [Errno -3] Temporary failure in name resolution')': /bot5019690287:AAH9nfL4sWzLiF5Tuza3Jf_DuqiFJZo8qqI/getUpdates
2022-01-07 22:33:07,342 - telegram.vendor.ptb_urllib3.urllib3.connectionpool - WARNING - Retrying (Retry(total=1, connect=None, read=None, redirect=None)) after connection broken by 'NewConnectionError('<telegram.vendor.ptb_urllib3.urllib3.connection.VerifiedHTTPSConnection object at 0x7f56d8296f40>: Failed to establish a new connection: [Errno -3] Temporary failure in name resolution')': /bot5019690287:AAH9nfL4sWzLiF5Tuza3Jf_DuqiFJZo8qqI/getUpdates
2022-01-07 22:33:07,344 - telegram.vendor.ptb_urllib3.urllib3.connectionpool - WARNING - Retrying (Retry(total=0, connect=None, read=None, redirect=None)) after connection broken by 'NewConnectionError('<telegram.vendor.ptb_urllib3.urllib3.connection.VerifiedHTTPSConnection object at 0x7f56d49f30d0>: Failed to establish a new connection: [Errno -3] Temporary failure in name resolution')': /bot5019690287:AAH9nfL4sWzLiF5Tuza3Jf_DuqiFJZo8qqI/getUpdates
2022-01-07 22:33:07,347 - telegram.ext.updater - ERROR - Error while getting Updates: urllib3 HTTPError HTTPSConnectionPool(host='api.telegram.org', port=443): Max retries exceeded with url: /bot5019690287:AAH9nfL4sWzLiF5Tuza3Jf_DuqiFJZo8qqI/getUpdates (Caused by NewConnectionError('<telegram.vendor.ptb_urllib3.urllib3.connection.VerifiedHTTPSConnection object at 0x7f56d49f3220>: Failed to establish a new connection: [Errno -3] Temporary failure in name resolution'))
2022-01-07 22:33:07,347 - __main__ - WARNING - [UPDATE] "None" causa del error "urllib3 HTTPError HTTPSConnectionPool(host='api.telegram.org', port=443): Max retries exceeded with url: /bot5019690287:AAH9nfL4sWzLiF5Tuza3Jf_DuqiFJZo8qqI/getUpdates (Caused by NewConnectionError('<telegram.vendor.ptb_urllib3.urllib3.connection.VerifiedHTTPSConnection object at 0x7f56d49f3220>: Failed to establish a new connection: [Errno -3] Temporary failure in name resolution'))"
2022-01-07 23:49:06,970 - telegram.vendor.ptb_urllib3.urllib3.connectionpool - WARNING - Retrying (Retry(total=2, connect=None, read=None, redirect=None)) after connection broken by 'NewConnectionError('<telegram.vendor.ptb_urllib3.urllib3.connection.VerifiedHTTPSConnection object at 0x7f56d49f3550>: Failed to establish a new connection: [Errno -3] Temporary failure in name resolution')': /bot5019690287:AAH9nfL4sWzLiF5Tuza3Jf_DuqiFJZo8qqI/getUpdates
2022-01-07 23:49:06,996 - telegram.vendor.ptb_urllib3.urllib3.connectionpool - WARNING - Retrying (Retry(total=1, connect=None, read=None, redirect=None)) after connection broken by 'NewConnectionError('<telegram.vendor.ptb_urllib3.urllib3.connection.VerifiedHTTPSConnection object at 0x7f56d49f37f0>: Failed to establish a new connection: [Errno -3] Temporary failure in name resolution')': /bot5019690287:AAH9nfL4sWzLiF5Tuza3Jf_DuqiFJZo8qqI/getUpdates
2022-01-07 23:49:07,004 - telegram.vendor.ptb_urllib3.urllib3.connectionpool - WARNING - Retrying (Retry(total=0, connect=None, read=None, redirect=None)) after connection broken by 'NewConnectionError('<telegram.vendor.ptb_urllib3.urllib3.connection.VerifiedHTTPSConnection object at 0x7f56d49f3940>: Failed to establish a new connection: [Errno -3] Temporary failure in name resolution')': /bot5019690287:AAH9nfL4sWzLiF5Tuza3Jf_DuqiFJZo8qqI/getUpdates
2022-01-07 23:49:07,048 - telegram.ext.updater - ERROR - Error while getting Updates: urllib3 HTTPError HTTPSConnectionPool(host='api.telegram.org', port=443): Max retries exceeded with url: /bot5019690287:AAH9nfL4sWzLiF5Tuza3Jf_DuqiFJZo8qqI/getUpdates (Caused by NewConnectionError('<telegram.vendor.ptb_urllib3.urllib3.connection.VerifiedHTTPSConnection object at 0x7f56d49f3a90>: Failed to establish a new connection: [Errno -3] Temporary failure in name resolution'))
2022-01-07 23:49:07,052 - __main__ - WARNING - [UPDATE] "None" causa del error "urllib3 HTTPError HTTPSConnectionPool(host='api.telegram.org', port=443): Max retries exceeded with url: /bot5019690287:AAH9nfL4sWzLiF5Tuza3Jf_DuqiFJZo8qqI/getUpdates (Caused by NewConnectionError('<telegram.vendor.ptb_urllib3.urllib3.connection.VerifiedHTTPSConnection object at 0x7f56d49f3a90>: Failed to establish a new connection: [Errno -3] Temporary failure in name resolution'))"
2022-01-07 23:49:08,061 - telegram.vendor.ptb_urllib3.urllib3.connectionpool - WARNING - Retrying (Retry(total=2, connect=None, read=None, redirect=None)) after connection broken by 'NewConnectionError('<telegram.vendor.ptb_urllib3.urllib3.connection.VerifiedHTTPSConnection object at 0x7f56d49f32b0>: Failed to establish a new connection: [Errno -3] Temporary failure in name resolution')': /bot5019690287:AAH9nfL4sWzLiF5Tuza3Jf_DuqiFJZo8qqI/getUpdates
2022-01-07 23:49:08,063 - telegram.vendor.ptb_urllib3.urllib3.connectionpool - WARNING - Retrying (Retry(total=1, connect=None, read=None, redirect=None)) after connection broken by 'NewConnectionError('<telegram.vendor.ptb_urllib3.urllib3.connection.VerifiedHTTPSConnection object at 0x7f56d49f3c40>: Failed to establish a new connection: [Errno -3] Temporary failure in name resolution')': /bot5019690287:AAH9nfL4sWzLiF5Tuza3Jf_DuqiFJZo8qqI/getUpdates
2022-01-07 23:49:08,066 - telegram.vendor.ptb_urllib3.urllib3.connectionpool - WARNING - Retrying (Retry(total=0, connect=None, read=None, redirect=None)) after connection broken by 'NewConnectionError('<telegram.vendor.ptb_urllib3.urllib3.connection.VerifiedHTTPSConnection object at 0x7f56d49f3d90>: Failed to establish a new connection: [Errno -3] Temporary failure in name resolution')': /bot5019690287:AAH9nfL4sWzLiF5Tuza3Jf_DuqiFJZo8qqI/getUpdates
2022-01-07 23:49:08,069 - telegram.ext.updater - ERROR - Error while getting Updates: urllib3 HTTPError HTTPSConnectionPool(host='api.telegram.org', port=443): Max retries exceeded with url: /bot5019690287:AAH9nfL4sWzLiF5Tuza3Jf_DuqiFJZo8qqI/getUpdates (Caused by NewConnectionError('<telegram.vendor.ptb_urllib3.urllib3.connection.VerifiedHTTPSConnection object at 0x7f56d49f3f10>: Failed to establish a new connection: [Errno -3] Temporary failure in name resolution'))
2022-01-07 23:49:08,069 - __main__ - WARNING - [UPDATE] "None" causa del error "urllib3 HTTPError HTTPSConnectionPool(host='api.telegram.org', port=443): Max retries exceeded with url: /bot5019690287:AAH9nfL4sWzLiF5Tuza3Jf_DuqiFJZo8qqI/getUpdates (Caused by NewConnectionError('<telegram.vendor.ptb_urllib3.urllib3.connection.VerifiedHTTPSConnection object at 0x7f56d49f3f10>: Failed to establish a new connection: [Errno -3] Temporary failure in name resolution'))"
2022-01-07 23:49:09,573 - telegram.vendor.ptb_urllib3.urllib3.connectionpool - WARNING - Retrying (Retry(total=2, connect=None, read=None, redirect=None)) after connection broken by 'NewConnectionError('<telegram.vendor.ptb_urllib3.urllib3.connection.VerifiedHTTPSConnection object at 0x7f56d49f31f0>: Failed to establish a new connection: [Errno -3] Temporary failure in name resolution')': /bot5019690287:AAH9nfL4sWzLiF5Tuza3Jf_DuqiFJZo8qqI/getUpdates
2022-01-07 23:49:09,577 - telegram.vendor.ptb_urllib3.urllib3.connectionpool - WARNING - Retrying (Retry(total=1, connect=None, read=None, redirect=None)) after connection broken by 'NewConnectionError('<telegram.vendor.ptb_urllib3.urllib3.connection.VerifiedHTTPSConnection object at 0x7f56d4a01190>: Failed to establish a new connection: [Errno -3] Temporary failure in name resolution')': /bot5019690287:AAH9nfL4sWzLiF5Tuza3Jf_DuqiFJZo8qqI/getUpdates
2022-01-07 23:49:09,580 - telegram.vendor.ptb_urllib3.urllib3.connectionpool - WARNING - Retrying (Retry(total=0, connect=None, read=None, redirect=None)) after connection broken by 'NewConnectionError('<telegram.vendor.ptb_urllib3.urllib3.connection.VerifiedHTTPSConnection object at 0x7f56d49f38e0>: Failed to establish a new connection: [Errno -3] Temporary failure in name resolution')': /bot5019690287:AAH9nfL4sWzLiF5Tuza3Jf_DuqiFJZo8qqI/getUpdates
2022-01-07 23:49:09,583 - telegram.ext.updater - ERROR - Error while getting Updates: urllib3 HTTPError HTTPSConnectionPool(host='api.telegram.org', port=443): Max retries exceeded with url: /bot5019690287:AAH9nfL4sWzLiF5Tuza3Jf_DuqiFJZo8qqI/getUpdates (Caused by NewConnectionError('<telegram.vendor.ptb_urllib3.urllib3.connection.VerifiedHTTPSConnection object at 0x7f56d49f3820>: Failed to establish a new connection: [Errno -3] Temporary failure in name resolution'))
2022-01-07 23:49:09,584 - __main__ - WARNING - [UPDATE] "None" causa del error "urllib3 HTTPError HTTPSConnectionPool(host='api.telegram.org', port=443): Max retries exceeded with url: /bot5019690287:AAH9nfL4sWzLiF5Tuza3Jf_DuqiFJZo8qqI/getUpdates (Caused by NewConnectionError('<telegram.vendor.ptb_urllib3.urllib3.connection.VerifiedHTTPSConnection object at 0x7f56d49f3820>: Failed to establish a new connection: [Errno -3] Temporary failure in name resolution'))"
2022-01-08 08:55:54,490 - telegram.vendor.ptb_urllib3.urllib3.connectionpool - WARNING - Retrying (Retry(total=2, connect=None, read=None, redirect=None)) after connection broken by 'NewConnectionError('<telegram.vendor.ptb_urllib3.urllib3.connection.VerifiedHTTPSConnection object at 0x7f56d8296ac0>: Failed to establish a new connection: [Errno -3] Temporary failure in name resolution')': /bot5019690287:AAH9nfL4sWzLiF5Tuza3Jf_DuqiFJZo8qqI/getUpdates
2022-01-08 08:55:54,492 - telegram.vendor.ptb_urllib3.urllib3.connectionpool - WARNING - Retrying (Retry(total=1, connect=None, read=None, redirect=None)) after connection broken by 'NewConnectionError('<telegram.vendor.ptb_urllib3.urllib3.connection.VerifiedHTTPSConnection object at 0x7f56d8296b50>: Failed to establish a new connection: [Errno -3] Temporary failure in name resolution')': /bot5019690287:AAH9nfL4sWzLiF5Tuza3Jf_DuqiFJZo8qqI/getUpdates
2022-01-08 08:55:54,494 - telegram.vendor.ptb_urllib3.urllib3.connectionpool - WARNING - Retrying (Retry(total=0, connect=None, read=None, redirect=None)) after connection broken by 'NewConnectionError('<telegram.vendor.ptb_urllib3.urllib3.connection.VerifiedHTTPSConnection object at 0x7f56d8296be0>: Failed to establish a new connection: [Errno -3] Temporary failure in name resolution')': /bot5019690287:AAH9nfL4sWzLiF5Tuza3Jf_DuqiFJZo8qqI/getUpdates
2022-01-08 08:55:54,498 - telegram.ext.updater - ERROR - Error while getting Updates: urllib3 HTTPError HTTPSConnectionPool(host='api.telegram.org', port=443): Max retries exceeded with url: /bot5019690287:AAH9nfL4sWzLiF5Tuza3Jf_DuqiFJZo8qqI/getUpdates (Caused by NewConnectionError('<telegram.vendor.ptb_urllib3.urllib3.connection.VerifiedHTTPSConnection object at 0x7f56d82962b0>: Failed to establish a new connection: [Errno -3] Temporary failure in name resolution'))
2022-01-08 08:55:54,498 - __main__ - WARNING - [UPDATE] "None" causa del error "urllib3 HTTPError HTTPSConnectionPool(host='api.telegram.org', port=443): Max retries exceeded with url: /bot5019690287:AAH9nfL4sWzLiF5Tuza3Jf_DuqiFJZo8qqI/getUpdates (Caused by NewConnectionError('<telegram.vendor.ptb_urllib3.urllib3.connection.VerifiedHTTPSConnection object at 0x7f56d82962b0>: Failed to establish a new connection: [Errno -3] Temporary failure in name resolution'))"
2022-01-08 09:06:35,925 - telegram.ext.updater - INFO - Received signal 2 (SIGINT), stopping...
2022-01-08 09:06:35,926 - apscheduler.scheduler - INFO - Scheduler has been shut down
2022-01-08 09:06:38,826 - root - INFO - InfiniemBot Iniciado...
2022-01-08 09:06:38,829 - apscheduler.scheduler - INFO - Scheduler started
2022-01-08 09:06:53,274 - root - INFO - [NEW ACCESS] chat_id : 1211957358 - firstname : Max - lastname : None - username None
2022-01-08 09:07:06,360 - __main__ - INFO - [UPDATE] Usuario Max consume el servicio /buscar üîé
2022-01-08 09:14:15,638 - root - INFO - [NEW ACCESS] chat_id : 1211957358 - firstname : Max - lastname : None - username None
2022-01-08 09:16:07,106 - __main__ - INFO - [UPDATE] Usuario Max consume el servicio /buscar
2022-01-08 09:43:24,982 - telegram.ext.updater - INFO - Received signal 2 (SIGINT), stopping...
2022-01-08 09:43:24,983 - apscheduler.scheduler - INFO - Scheduler has been shut down
2022-01-08 09:43:25,673 - telegram.ext.updater - WARNING - Exiting immediately!
2022-01-08 09:43:28,300 - root - INFO - InfiniemBot Iniciado...
2022-01-08 09:43:28,305 - apscheduler.scheduler - INFO - Scheduler started
2022-01-08 09:44:28,052 - telegram.ext.updater - INFO - Received signal 2 (SIGINT), stopping...
2022-01-08 09:44:28,053 - apscheduler.scheduler - INFO - Scheduler has been shut down
2022-01-08 09:44:28,345 - telegram.ext.updater - WARNING - Exiting immediately!
2022-01-08 09:44:30,011 - root - INFO - InfiniemBot Iniciado...
2022-01-08 09:44:30,013 - apscheduler.scheduler - INFO - Scheduler started
2022-01-08 09:57:46,622 - root - INFO - [NEW ACCESS] chat_id : 1211957358 - firstname : Max - lastname : None - username None
2022-01-08 09:57:53,542 - __main__ - INFO - [UPDATE] Usuario Max consume el servicio /buscar üîé
2022-01-08 10:07:06,422 - telegram.ext.updater - INFO - Received signal 2 (SIGINT), stopping...
2022-01-08 10:07:06,422 - apscheduler.scheduler - INFO - Scheduler has been shut down
2022-01-08 10:07:06,713 - telegram.ext.updater - WARNING - Exiting immediately!
2022-01-08 10:07:19,746 - root - INFO - InfiniemBot Iniciado...
2022-01-08 10:07:19,750 - apscheduler.scheduler - INFO - Scheduler started
2022-01-08 10:07:28,888 - __main__ - INFO - [UPDATE] Usuario Max consume el servicio /buscar üîé
2022-01-08 10:09:30,286 - telegram.ext.updater - INFO - Received signal 2 (SIGINT), stopping...
2022-01-08 10:09:30,286 - apscheduler.scheduler - INFO - Scheduler has been shut down
2022-01-08 10:09:30,753 - telegram.ext.updater - WARNING - Exiting immediately!
2022-01-08 10:09:34,317 - root - INFO - InfiniemBot Iniciado...
2022-01-08 10:09:34,320 - apscheduler.scheduler - INFO - Scheduler started
2022-01-08 10:09:48,001 - telegram.ext.updater - INFO - Received signal 2 (SIGINT), stopping...
2022-01-08 10:09:48,002 - apscheduler.scheduler - INFO - Scheduler has been shut down
2022-01-08 10:10:25,074 - root - INFO - InfiniemBot Iniciado...
2022-01-08 10:10:25,076 - apscheduler.scheduler - INFO - Scheduler started
2022-01-08 10:19:44,340 - telegram.ext.updater - INFO - Received signal 2 (SIGINT), stopping...
2022-01-08 10:19:44,343 - apscheduler.scheduler - INFO - Scheduler has been shut down
2022-01-08 10:19:45,453 - telegram.ext.updater - WARNING - Exiting immediately!
2022-01-08 10:19:52,845 - root - INFO - InfiniemBot Iniciado...
2022-01-08 10:19:52,847 - apscheduler.scheduler - INFO - Scheduler started
2022-01-08 10:19:56,653 - __main__ - INFO - [UPDATE] Usuario Max consume el servicio /buscar
2022-01-08 10:20:03,385 - __main__ - WARNING - [UPDATE] "{'message': {'supergroup_chat_created': False, 'date': 1641648003, 'delete_chat_photo': False, 'entities': [{'type': 'bot_command', 'offset': 0, 'length': 13}], 'text': '/mensaje_maxi', 'message_id': 358, 'caption_entities': [], 'group_chat_created': False, 'chat': {'type': 'private', 'first_name': 'Max', 'id': 1211957358}, 'channel_chat_created': False, 'new_chat_photo': [], 'new_chat_members': [], 'photo': [], 'from': {'language_code': 'en', 'first_name': 'Max', 'id': 1211957358, 'is_bot': False}}, 'update_id': 197674712}" causa del error "mensaje_maxi() missing 1 required positional argument: 'args'"
2022-01-08 10:20:29,401 - __main__ - WARNING - [UPDATE] "{'message': {'supergroup_chat_created': False, 'date': 1641648029, 'delete_chat_photo': False, 'entities': [{'type': 'bot_command', 'offset': 0, 'length': 13}], 'text': '/mensaje_maxi', 'message_id': 359, 'caption_entities': [], 'group_chat_created': False, 'chat': {'type': 'private', 'first_name': 'Max', 'id': 1211957358}, 'channel_chat_created': False, 'new_chat_photo': [], 'new_chat_members': [], 'photo': [], 'from': {'language_code': 'en', 'first_name': 'Max', 'id': 1211957358, 'is_bot': False}}, 'update_id': 197674713}" causa del error "mensaje_maxi() missing 1 required positional argument: 'args'"
2022-01-08 10:29:03,990 - telegram.ext.updater - INFO - Received signal 2 (SIGINT), stopping...
2022-01-08 10:29:03,992 - apscheduler.scheduler - INFO - Scheduler has been shut down
2022-01-08 10:29:05,080 - telegram.ext.updater - WARNING - Exiting immediately!
2022-01-08 10:29:19,261 - root - INFO - InfiniemBot Iniciado...
2022-01-08 10:29:19,265 - apscheduler.scheduler - INFO - Scheduler started
2022-01-08 10:29:25,771 - __main__ - INFO - [UPDATE] Usuario Max consume el servicio /buscar
2022-01-08 10:29:26,795 - __main__ - INFO - [UPDATE] Usuario Max consume el servicio /buscar
2022-01-08 10:37:12,321 - telegram.ext.updater - INFO - Received signal 2 (SIGINT), stopping...
2022-01-08 10:37:12,326 - apscheduler.scheduler - INFO - Scheduler has been shut down
2022-01-08 10:37:13,682 - telegram.ext.updater - WARNING - Exiting immediately!
2022-01-08 10:37:16,664 - root - INFO - InfiniemBot Iniciado...
2022-01-08 10:37:16,666 - apscheduler.scheduler - INFO - Scheduler started
2022-01-08 10:38:06,409 - __main__ - WARNING - [UPDATE] "{'message': {'group_chat_created': False, 'caption_entities': [], 'text': '/mensaje hernan', 'new_chat_photo': [], 'message_id': 366, 'photo': [], 'date': 1641649086, 'supergroup_chat_created': False, 'entities': [{'type': 'bot_command', 'length': 8, 'offset': 0}], 'new_chat_members': [], 'chat': {'id': 1211957358, 'type': 'private', 'first_name': 'Max'}, 'delete_chat_photo': False, 'channel_chat_created': False, 'from': {'language_code': 'en', 'first_name': 'Max', 'id': 1211957358, 'is_bot': False}}, 'update_id': 197674718}" causa del error "mensaje() missing 1 required positional argument: 'args'"
2022-01-08 10:39:14,451 - telegram.ext.updater - INFO - Received signal 2 (SIGINT), stopping...
2022-01-08 10:39:14,452 - apscheduler.scheduler - INFO - Scheduler has been shut down
2022-01-08 10:39:14,829 - telegram.ext.updater - WARNING - Exiting immediately!
2022-01-08 10:39:46,692 - root - INFO - InfiniemBot Iniciado...
2022-01-08 10:39:46,694 - apscheduler.scheduler - INFO - Scheduler started
2022-01-08 10:39:49,201 - __main__ - WARNING - [UPDATE] "{'update_id': 197674719, 'message': {'group_chat_created': False, 'channel_chat_created': False, 'new_chat_members': [], 'entities': [{'type': 'bot_command', 'length': 8, 'offset': 0}], 'new_chat_photo': [], 'chat': {'type': 'private', 'id': 1211957358, 'first_name': 'Max'}, 'photo': [], 'date': 1641649188, 'message_id': 367, 'supergroup_chat_created': False, 'delete_chat_photo': False, 'caption_entities': [], 'text': '/mensaje', 'from': {'language_code': 'en', 'is_bot': False, 'id': 1211957358, 'first_name': 'Max'}}}" causa del error "mensaje() missing 1 required positional argument: 'args'"
2022-01-08 10:39:52,726 - __main__ - WARNING - [UPDATE] "{'update_id': 197674720, 'message': {'group_chat_created': False, 'channel_chat_created': False, 'new_chat_members': [], 'entities': [{'type': 'bot_command', 'length': 8, 'offset': 0}], 'new_chat_photo': [], 'chat': {'type': 'private', 'id': 1211957358, 'first_name': 'Max'}, 'photo': [], 'date': 1641649192, 'message_id': 368, 'supergroup_chat_created': False, 'delete_chat_photo': False, 'caption_entities': [], 'text': '/mensaje', 'from': {'language_code': 'en', 'is_bot': False, 'id': 1211957358, 'first_name': 'Max'}}}" causa del error "mensaje() missing 1 required positional argument: 'args'"
2022-01-08 10:40:31,047 - telegram.ext.updater - INFO - Received signal 2 (SIGINT), stopping...
2022-01-08 10:40:31,047 - apscheduler.scheduler - INFO - Scheduler has been shut down
2022-01-08 10:40:31,619 - telegram.ext.updater - WARNING - Exiting immediately!
2022-01-08 10:40:33,649 - root - INFO - InfiniemBot Iniciado...
2022-01-08 10:40:33,651 - apscheduler.scheduler - INFO - Scheduler started
2022-01-08 10:40:37,414 - __main__ - WARNING - [UPDATE] "{'message': {'message_id': 369, 'new_chat_members': [], 'date': 1641649237, 'delete_chat_photo': False, 'text': '/mensaje', 'photo': [], 'group_chat_created': False, 'entities': [{'length': 8, 'offset': 0, 'type': 'bot_command'}], 'chat': {'first_name': 'Max', 'type': 'private', 'id': 1211957358}, 'caption_entities': [], 'new_chat_photo': [], 'supergroup_chat_created': False, 'channel_chat_created': False, 'from': {'id': 1211957358, 'language_code': 'en', 'is_bot': False, 'first_name': 'Max'}}, 'update_id': 197674721}" causa del error "mensaje() missing 1 required positional argument: 'args'"
2022-01-08 10:40:41,375 - __main__ - WARNING - [UPDATE] "{'message': {'message_id': 370, 'new_chat_members': [], 'date': 1641649241, 'delete_chat_photo': False, 'text': '/mensaje', 'photo': [], 'group_chat_created': False, 'entities': [{'length': 8, 'offset': 0, 'type': 'bot_command'}], 'chat': {'first_name': 'Max', 'type': 'private', 'id': 1211957358}, 'caption_entities': [], 'new_chat_photo': [], 'supergroup_chat_created': False, 'channel_chat_created': False, 'from': {'id': 1211957358, 'language_code': 'en', 'is_bot': False, 'first_name': 'Max'}}, 'update_id': 197674722}" causa del error "mensaje() missing 1 required positional argument: 'args'"
2022-01-08 10:40:58,060 - __main__ - WARNING - [UPDATE] "{'edited_message': {'message_id': 370, 'new_chat_members': [], 'date': 1641649241, 'delete_chat_photo': False, 'text': '/mensaje a', 'photo': [], 'group_chat_created': False, 'entities': [{'length': 8, 'offset': 0, 'type': 'bot_command'}], 'edit_date': 1641649257, 'chat': {'first_name': 'Max', 'type': 'private', 'id': 1211957358}, 'caption_entities': [], 'new_chat_photo': [], 'supergroup_chat_created': False, 'channel_chat_created': False, 'from': {'id': 1211957358, 'language_code': 'en', 'is_bot': False, 'first_name': 'Max'}}, 'update_id': 197674723}" causa del error "mensaje() missing 1 required positional argument: 'args'"
2022-01-08 10:42:28,780 - telegram.ext.updater - INFO - Received signal 2 (SIGINT), stopping...
2022-01-08 10:42:28,781 - apscheduler.scheduler - INFO - Scheduler has been shut down
2022-01-08 10:42:29,820 - telegram.ext.updater - WARNING - Exiting immediately!
2022-01-08 10:42:31,636 - root - INFO - InfiniemBot Iniciado...
2022-01-08 10:42:31,638 - apscheduler.scheduler - INFO - Scheduler started
2022-01-08 10:42:41,243 - __main__ - WARNING - [UPDATE] "{'message': {'forward_from': {'language_code': 'en', 'id': 1211957358, 'first_name': 'Max', 'is_bot': False}, 'group_chat_created': False, 'forward_date': 1641649241, 'caption_entities': [], 'text': '/mensaje a', 'message_id': 371, 'channel_chat_created': False, 'date': 1641649361, 'new_chat_members': [], 'photo': [], 'supergroup_chat_created': False, 'delete_chat_photo': False, 'chat': {'type': 'private', 'id': 1211957358, 'first_name': 'Max'}, 'entities': [{'type': 'bot_command', 'offset': 0, 'length': 8}], 'new_chat_photo': [], 'from': {'language_code': 'en', 'id': 1211957358, 'first_name': 'Max', 'is_bot': False}}, 'update_id': 197674724}" causa del error "mensaje() missing 1 required positional argument: 'args'"
2022-01-08 10:42:49,370 - __main__ - WARNING - [UPDATE] "{'message': {'group_chat_created': False, 'caption_entities': [], 'text': '/mensaje', 'message_id': 372, 'channel_chat_created': False, 'date': 1641649369, 'new_chat_members': [], 'photo': [], 'supergroup_chat_created': False, 'delete_chat_photo': False, 'chat': {'type': 'private', 'id': 1211957358, 'first_name': 'Max'}, 'entities': [{'type': 'bot_command', 'offset': 0, 'length': 8}], 'new_chat_photo': [], 'from': {'language_code': 'en', 'id': 1211957358, 'first_name': 'Max', 'is_bot': False}}, 'update_id': 197674725}" causa del error "mensaje() missing 1 required positional argument: 'args'"
2022-01-08 10:42:54,755 - __main__ - WARNING - [UPDATE] "{'edited_message': {'group_chat_created': False, 'caption_entities': [], 'text': '/mensaje lsaka', 'message_id': 372, 'channel_chat_created': False, 'date': 1641649369, 'new_chat_members': [], 'photo': [], 'supergroup_chat_created': False, 'edit_date': 1641649374, 'delete_chat_photo': False, 'chat': {'type': 'private', 'id': 1211957358, 'first_name': 'Max'}, 'entities': [{'type': 'bot_command', 'offset': 0, 'length': 8}], 'new_chat_photo': [], 'from': {'language_code': 'en', 'id': 1211957358, 'first_name': 'Max', 'is_bot': False}}, 'update_id': 197674726}" causa del error "mensaje() missing 1 required positional argument: 'args'"
2022-01-08 10:44:20,045 - __main__ - WARNING - [UPDATE] "{'message': {'group_chat_created': False, 'caption_entities': [], 'text': '/mensaje hehe ehe', 'message_id': 373, 'channel_chat_created': False, 'date': 1641649459, 'new_chat_members': [], 'photo': [], 'supergroup_chat_created': False, 'delete_chat_photo': False, 'chat': {'type': 'private', 'id': 1211957358, 'first_name': 'Max'}, 'entities': [{'type': 'bot_command', 'offset': 0, 'length': 8}], 'new_chat_photo': [], 'from': {'language_code': 'en', 'id': 1211957358, 'first_name': 'Max', 'is_bot': False}}, 'update_id': 197674727}" causa del error "mensaje() missing 1 required positional argument: 'args'"
2022-01-08 10:55:07,299 - telegram.ext.updater - INFO - Received signal 2 (SIGINT), stopping...
2022-01-08 10:55:07,300 - apscheduler.scheduler - INFO - Scheduler has been shut down
2022-01-08 10:55:07,944 - telegram.ext.updater - WARNING - Exiting immediately!
2022-01-08 10:55:10,923 - root - INFO - InfiniemBot Iniciado...
2022-01-08 10:55:10,926 - apscheduler.scheduler - INFO - Scheduler started
2022-01-08 10:58:22,289 - telegram.ext.updater - INFO - Received signal 2 (SIGINT), stopping...
2022-01-08 10:58:22,290 - apscheduler.scheduler - INFO - Scheduler has been shut down
2022-01-08 10:58:22,531 - telegram.ext.updater - WARNING - Exiting immediately!
2022-01-08 10:58:27,796 - root - INFO - InfiniemBot Iniciado...
2022-01-08 10:58:27,798 - apscheduler.scheduler - INFO - Scheduler started
2022-01-08 11:13:42,519 - telegram.ext.updater - INFO - Received signal 2 (SIGINT), stopping...
2022-01-08 11:13:42,520 - apscheduler.scheduler - INFO - Scheduler has been shut down
2022-01-08 11:13:42,753 - telegram.ext.updater - WARNING - Exiting immediately!
2022-01-08 11:13:44,820 - root - INFO - InfiniemBot Iniciado...
2022-01-08 11:13:44,823 - apscheduler.scheduler - INFO - Scheduler started
2022-01-08 11:13:51,273 - __main__ - INFO - [UPDATE] Usuario Max consume el servicio /buscar üîé
2022-01-08 11:13:54,916 - __main__ - WARNING - [UPDATE] "{'update_id': 197674731, 'callback_query': {'data': '/mensaje', 'chat_instance': '-790424824538411994', 'id': '5205317218130979503', 'message': {'new_chat_photo': [], 'group_chat_created': False, 'new_chat_members': [], 'supergroup_chat_created': False, 'channel_chat_created': False, 'entities': [], 'reply_markup': {'inline_keyboard': [[{'text': 'Hernan', 'callback_data': '/mensaje'}], [{'text': 'Maxi', 'callback_data': '/mensaje'}]]}, 'date': 1641651232, 'caption_entities': [], 'chat': {'type': 'private', 'first_name': 'Max', 'id': 1211957358}, 'photo': [], 'delete_chat_photo': False, 'text': '¬øA qui√©n estas buscando? Te ayudo mandandole un msj a:', 'message_id': 375, 'from': {'username': 'InfiniemBot', 'id': 5019690287, 'first_name': 'MecaBot', 'is_bot': True}}, 'from': {'language_code': 'en', 'id': 1211957358, 'first_name': 'Max', 'is_bot': False}}}" causa del error "'NoneType' object has no attribute 'reply_text'"
2022-01-08 11:14:28,064 - __main__ - WARNING - [UPDATE] "{'update_id': 197674732, 'message': {'new_chat_photo': [], 'group_chat_created': False, 'new_chat_members': [], 'supergroup_chat_created': False, 'channel_chat_created': False, 'entities': [{'type': 'bot_command', 'length': 8, 'offset': 0}], 'date': 1641651267, 'caption_entities': [], 'chat': {'type': 'private', 'first_name': 'Max', 'id': 1211957358}, 'photo': [], 'delete_chat_photo': False, 'text': '/mensaje', 'message_id': 376, 'from': {'language_code': 'en', 'id': 1211957358, 'first_name': 'Max', 'is_bot': False}}}" causa del error "list index out of range"
2022-01-08 11:36:46,381 - telegram.vendor.ptb_urllib3.urllib3.connectionpool - WARNING - Retrying (Retry(total=2, connect=None, read=None, redirect=None)) after connection broken by 'NewConnectionError('<telegram.vendor.ptb_urllib3.urllib3.connection.VerifiedHTTPSConnection object at 0x7ff24b23f6a0>: Failed to establish a new connection: [Errno -3] Temporary failure in name resolution')': /bot5019690287:AAH9nfL4sWzLiF5Tuza3Jf_DuqiFJZo8qqI/getUpdates
2022-01-08 11:36:46,398 - telegram.vendor.ptb_urllib3.urllib3.connectionpool - WARNING - Retrying (Retry(total=1, connect=None, read=None, redirect=None)) after connection broken by 'NewConnectionError('<telegram.vendor.ptb_urllib3.urllib3.connection.VerifiedHTTPSConnection object at 0x7ff24b23f8e0>: Failed to establish a new connection: [Errno -3] Temporary failure in name resolution')': /bot5019690287:AAH9nfL4sWzLiF5Tuza3Jf_DuqiFJZo8qqI/getUpdates
2022-01-08 11:36:46,400 - telegram.vendor.ptb_urllib3.urllib3.connectionpool - WARNING - Retrying (Retry(total=0, connect=None, read=None, redirect=None)) after connection broken by 'NewConnectionError('<telegram.vendor.ptb_urllib3.urllib3.connection.VerifiedHTTPSConnection object at 0x7ff24b23fb80>: Failed to establish a new connection: [Errno -3] Temporary failure in name resolution')': /bot5019690287:AAH9nfL4sWzLiF5Tuza3Jf_DuqiFJZo8qqI/getUpdates
2022-01-08 11:36:46,406 - telegram.ext.updater - ERROR - Error while getting Updates: urllib3 HTTPError HTTPSConnectionPool(host='api.telegram.org', port=443): Max retries exceeded with url: /bot5019690287:AAH9nfL4sWzLiF5Tuza3Jf_DuqiFJZo8qqI/getUpdates (Caused by NewConnectionError('<telegram.vendor.ptb_urllib3.urllib3.connection.VerifiedHTTPSConnection object at 0x7ff24b23fcd0>: Failed to establish a new connection: [Errno -3] Temporary failure in name resolution'))
2022-01-08 11:36:46,410 - __main__ - WARNING - [UPDATE] "None" causa del error "urllib3 HTTPError HTTPSConnectionPool(host='api.telegram.org', port=443): Max retries exceeded with url: /bot5019690287:AAH9nfL4sWzLiF5Tuza3Jf_DuqiFJZo8qqI/getUpdates (Caused by NewConnectionError('<telegram.vendor.ptb_urllib3.urllib3.connection.VerifiedHTTPSConnection object at 0x7ff24b23fcd0>: Failed to establish a new connection: [Errno -3] Temporary failure in name resolution'))"
2022-01-08 11:36:47,409 - telegram.vendor.ptb_urllib3.urllib3.connectionpool - WARNING - Retrying (Retry(total=2, connect=None, read=None, redirect=None)) after connection broken by 'NewConnectionError('<telegram.vendor.ptb_urllib3.urllib3.connection.VerifiedHTTPSConnection object at 0x7ff24b23f790>: Failed to establish a new connection: [Errno -3] Temporary failure in name resolution')': /bot5019690287:AAH9nfL4sWzLiF5Tuza3Jf_DuqiFJZo8qqI/getUpdates
2022-01-08 11:36:47,410 - telegram.vendor.ptb_urllib3.urllib3.connectionpool - WARNING - Retrying (Retry(total=1, connect=None, read=None, redirect=None)) after connection broken by 'NewConnectionError('<telegram.vendor.ptb_urllib3.urllib3.connection.VerifiedHTTPSConnection object at 0x7ff24b23f520>: Failed to establish a new connection: [Errno -3] Temporary failure in name resolution')': /bot5019690287:AAH9nfL4sWzLiF5Tuza3Jf_DuqiFJZo8qqI/getUpdates
2022-01-08 11:36:47,412 - telegram.vendor.ptb_urllib3.urllib3.connectionpool - WARNING - Retrying (Retry(total=0, connect=None, read=None, redirect=None)) after connection broken by 'NewConnectionError('<telegram.vendor.ptb_urllib3.urllib3.connection.VerifiedHTTPSConnection object at 0x7ff24b23fe20>: Failed to establish a new connection: [Errno -3] Temporary failure in name resolution')': /bot5019690287:AAH9nfL4sWzLiF5Tuza3Jf_DuqiFJZo8qqI/getUpdates
2022-01-08 11:36:47,414 - telegram.ext.updater - ERROR - Error while getting Updates: urllib3 HTTPError HTTPSConnectionPool(host='api.telegram.org', port=443): Max retries exceeded with url: /bot5019690287:AAH9nfL4sWzLiF5Tuza3Jf_DuqiFJZo8qqI/getUpdates (Caused by NewConnectionError('<telegram.vendor.ptb_urllib3.urllib3.connection.VerifiedHTTPSConnection object at 0x7ff24b23ff70>: Failed to establish a new connection: [Errno -3] Temporary failure in name resolution'))
2022-01-08 11:36:47,414 - __main__ - WARNING - [UPDATE] "None" causa del error "urllib3 HTTPError HTTPSConnectionPool(host='api.telegram.org', port=443): Max retries exceeded with url: /bot5019690287:AAH9nfL4sWzLiF5Tuza3Jf_DuqiFJZo8qqI/getUpdates (Caused by NewConnectionError('<telegram.vendor.ptb_urllib3.urllib3.connection.VerifiedHTTPSConnection object at 0x7ff24b23ff70>: Failed to establish a new connection: [Errno -3] Temporary failure in name resolution'))"
2022-01-08 11:36:48,917 - telegram.vendor.ptb_urllib3.urllib3.connectionpool - WARNING - Retrying (Retry(total=2, connect=None, read=None, redirect=None)) after connection broken by 'NewConnectionError('<telegram.vendor.ptb_urllib3.urllib3.connection.VerifiedHTTPSConnection object at 0x7ff24b228ac0>: Failed to establish a new connection: [Errno -3] Temporary failure in name resolution')': /bot5019690287:AAH9nfL4sWzLiF5Tuza3Jf_DuqiFJZo8qqI/getUpdates
2022-01-08 11:36:48,919 - telegram.vendor.ptb_urllib3.urllib3.connectionpool - WARNING - Retrying (Retry(total=1, connect=None, read=None, redirect=None)) after connection broken by 'NewConnectionError('<telegram.vendor.ptb_urllib3.urllib3.connection.VerifiedHTTPSConnection object at 0x7ff248198160>: Failed to establish a new connection: [Errno -3] Temporary failure in name resolution')': /bot5019690287:AAH9nfL4sWzLiF5Tuza3Jf_DuqiFJZo8qqI/getUpdates
2022-01-08 11:36:48,921 - telegram.vendor.ptb_urllib3.urllib3.connectionpool - WARNING - Retrying (Retry(total=0, connect=None, read=None, redirect=None)) after connection broken by 'NewConnectionError('<telegram.vendor.ptb_urllib3.urllib3.connection.VerifiedHTTPSConnection object at 0x7ff2481982b0>: Failed to establish a new connection: [Errno -3] Temporary failure in name resolution')': /bot5019690287:AAH9nfL4sWzLiF5Tuza3Jf_DuqiFJZo8qqI/getUpdates
2022-01-08 11:36:48,923 - telegram.ext.updater - ERROR - Error while getting Updates: urllib3 HTTPError HTTPSConnectionPool(host='api.telegram.org', port=443): Max retries exceeded with url: /bot5019690287:AAH9nfL4sWzLiF5Tuza3Jf_DuqiFJZo8qqI/getUpdates (Caused by NewConnectionError('<telegram.vendor.ptb_urllib3.urllib3.connection.VerifiedHTTPSConnection object at 0x7ff248198400>: Failed to establish a new connection: [Errno -3] Temporary failure in name resolution'))
2022-01-08 11:36:48,924 - __main__ - WARNING - [UPDATE] "None" causa del error "urllib3 HTTPError HTTPSConnectionPool(host='api.telegram.org', port=443): Max retries exceeded with url: /bot5019690287:AAH9nfL4sWzLiF5Tuza3Jf_DuqiFJZo8qqI/getUpdates (Caused by NewConnectionError('<telegram.vendor.ptb_urllib3.urllib3.connection.VerifiedHTTPSConnection object at 0x7ff248198400>: Failed to establish a new connection: [Errno -3] Temporary failure in name resolution'))"
2022-01-08 11:40:52,969 - telegram.vendor.ptb_urllib3.urllib3.connectionpool - WARNING - Retrying (Retry(total=2, connect=None, read=None, redirect=None)) after connection broken by 'NewConnectionError('<telegram.vendor.ptb_urllib3.urllib3.connection.VerifiedHTTPSConnection object at 0x7ff248198820>: Failed to establish a new connection: [Errno -3] Temporary failure in name resolution')': /bot5019690287:AAH9nfL4sWzLiF5Tuza3Jf_DuqiFJZo8qqI/getUpdates
2022-01-08 11:40:52,972 - telegram.vendor.ptb_urllib3.urllib3.connectionpool - WARNING - Retrying (Retry(total=1, connect=None, read=None, redirect=None)) after connection broken by 'NewConnectionError('<telegram.vendor.ptb_urllib3.urllib3.connection.VerifiedHTTPSConnection object at 0x7ff2481989d0>: Failed to establish a new connection: [Errno -3] Temporary failure in name resolution')': /bot5019690287:AAH9nfL4sWzLiF5Tuza3Jf_DuqiFJZo8qqI/getUpdates
2022-01-08 11:40:52,975 - telegram.vendor.ptb_urllib3.urllib3.connectionpool - WARNING - Retrying (Retry(total=0, connect=None, read=None, redirect=None)) after connection broken by 'NewConnectionError('<telegram.vendor.ptb_urllib3.urllib3.connection.VerifiedHTTPSConnection object at 0x7ff248198b20>: Failed to establish a new connection: [Errno -3] Temporary failure in name resolution')': /bot5019690287:AAH9nfL4sWzLiF5Tuza3Jf_DuqiFJZo8qqI/getUpdates
2022-01-08 11:40:52,979 - telegram.ext.updater - ERROR - Error while getting Updates: urllib3 HTTPError HTTPSConnectionPool(host='api.telegram.org', port=443): Max retries exceeded with url: /bot5019690287:AAH9nfL4sWzLiF5Tuza3Jf_DuqiFJZo8qqI/getUpdates (Caused by NewConnectionError('<telegram.vendor.ptb_urllib3.urllib3.connection.VerifiedHTTPSConnection object at 0x7ff248198c70>: Failed to establish a new connection: [Errno -3] Temporary failure in name resolution'))
2022-01-08 11:40:52,980 - __main__ - WARNING - [UPDATE] "None" causa del error "urllib3 HTTPError HTTPSConnectionPool(host='api.telegram.org', port=443): Max retries exceeded with url: /bot5019690287:AAH9nfL4sWzLiF5Tuza3Jf_DuqiFJZo8qqI/getUpdates (Caused by NewConnectionError('<telegram.vendor.ptb_urllib3.urllib3.connection.VerifiedHTTPSConnection object at 0x7ff248198c70>: Failed to establish a new connection: [Errno -3] Temporary failure in name resolution'))"
2022-01-08 11:40:53,984 - telegram.vendor.ptb_urllib3.urllib3.connectionpool - WARNING - Retrying (Retry(total=2, connect=None, read=None, redirect=None)) after connection broken by 'NewConnectionError('<telegram.vendor.ptb_urllib3.urllib3.connection.VerifiedHTTPSConnection object at 0x7ff248198490>: Failed to establish a new connection: [Errno -3] Temporary failure in name resolution')': /bot5019690287:AAH9nfL4sWzLiF5Tuza3Jf_DuqiFJZo8qqI/getUpdates
2022-01-08 11:40:53,989 - telegram.vendor.ptb_urllib3.urllib3.connectionpool - WARNING - Retrying (Retry(total=1, connect=None, read=None, redirect=None)) after connection broken by 'NewConnectionError('<telegram.vendor.ptb_urllib3.urllib3.connection.VerifiedHTTPSConnection object at 0x7ff248198e20>: Failed to establish a new connection: [Errno -3] Temporary failure in name resolution')': /bot5019690287:AAH9nfL4sWzLiF5Tuza3Jf_DuqiFJZo8qqI/getUpdates
2022-01-08 11:40:53,991 - telegram.vendor.ptb_urllib3.urllib3.connectionpool - WARNING - Retrying (Retry(total=0, connect=None, read=None, redirect=None)) after connection broken by 'NewConnectionError('<telegram.vendor.ptb_urllib3.urllib3.connection.VerifiedHTTPSConnection object at 0x7ff248198f70>: Failed to establish a new connection: [Errno -3] Temporary failure in name resolution')': /bot5019690287:AAH9nfL4sWzLiF5Tuza3Jf_DuqiFJZo8qqI/getUpdates
2022-01-08 11:40:53,995 - telegram.ext.updater - ERROR - Error while getting Updates: urllib3 HTTPError HTTPSConnectionPool(host='api.telegram.org', port=443): Max retries exceeded with url: /bot5019690287:AAH9nfL4sWzLiF5Tuza3Jf_DuqiFJZo8qqI/getUpdates (Caused by NewConnectionError('<telegram.vendor.ptb_urllib3.urllib3.connection.VerifiedHTTPSConnection object at 0x7ff2481ac130>: Failed to establish a new connection: [Errno -3] Temporary failure in name resolution'))
2022-01-08 11:40:53,996 - __main__ - WARNING - [UPDATE] "None" causa del error "urllib3 HTTPError HTTPSConnectionPool(host='api.telegram.org', port=443): Max retries exceeded with url: /bot5019690287:AAH9nfL4sWzLiF5Tuza3Jf_DuqiFJZo8qqI/getUpdates (Caused by NewConnectionError('<telegram.vendor.ptb_urllib3.urllib3.connection.VerifiedHTTPSConnection object at 0x7ff2481ac130>: Failed to establish a new connection: [Errno -3] Temporary failure in name resolution'))"
2022-01-08 11:40:55,500 - telegram.vendor.ptb_urllib3.urllib3.connectionpool - WARNING - Retrying (Retry(total=2, connect=None, read=None, redirect=None)) after connection broken by 'NewConnectionError('<telegram.vendor.ptb_urllib3.urllib3.connection.VerifiedHTTPSConnection object at 0x7ff2481983d0>: Failed to establish a new connection: [Errno -3] Temporary failure in name resolution')': /bot5019690287:AAH9nfL4sWzLiF5Tuza3Jf_DuqiFJZo8qqI/getUpdates
2022-01-08 11:40:55,505 - telegram.vendor.ptb_urllib3.urllib3.connectionpool - WARNING - Retrying (Retry(total=1, connect=None, read=None, redirect=None)) after connection broken by 'NewConnectionError('<telegram.vendor.ptb_urllib3.urllib3.connection.VerifiedHTTPSConnection object at 0x7ff2481ac370>: Failed to establish a new connection: [Errno -3] Temporary failure in name resolution')': /bot5019690287:AAH9nfL4sWzLiF5Tuza3Jf_DuqiFJZo8qqI/getUpdates
2022-01-08 11:40:55,506 - telegram.vendor.ptb_urllib3.urllib3.connectionpool - WARNING - Retrying (Retry(total=0, connect=None, read=None, redirect=None)) after connection broken by 'NewConnectionError('<telegram.vendor.ptb_urllib3.urllib3.connection.VerifiedHTTPSConnection object at 0x7ff248198b50>: Failed to establish a new connection: [Errno -3] Temporary failure in name resolution')': /bot5019690287:AAH9nfL4sWzLiF5Tuza3Jf_DuqiFJZo8qqI/getUpdates
2022-01-08 11:40:55,508 - telegram.ext.updater - ERROR - Error while getting Updates: urllib3 HTTPError HTTPSConnectionPool(host='api.telegram.org', port=443): Max retries exceeded with url: /bot5019690287:AAH9nfL4sWzLiF5Tuza3Jf_DuqiFJZo8qqI/getUpdates (Caused by NewConnectionError('<telegram.vendor.ptb_urllib3.urllib3.connection.VerifiedHTTPSConnection object at 0x7ff248198a90>: Failed to establish a new connection: [Errno -3] Temporary failure in name resolution'))
2022-01-08 11:40:55,508 - __main__ - WARNING - [UPDATE] "None" causa del error "urllib3 HTTPError HTTPSConnectionPool(host='api.telegram.org', port=443): Max retries exceeded with url: /bot5019690287:AAH9nfL4sWzLiF5Tuza3Jf_DuqiFJZo8qqI/getUpdates (Caused by NewConnectionError('<telegram.vendor.ptb_urllib3.urllib3.connection.VerifiedHTTPSConnection object at 0x7ff248198a90>: Failed to establish a new connection: [Errno -3] Temporary failure in name resolution'))"
2022-01-08 11:51:40,803 - telegram.vendor.ptb_urllib3.urllib3.connectionpool - WARNING - Retrying (Retry(total=2, connect=None, read=None, redirect=None)) after connection broken by 'NewConnectionError('<telegram.vendor.ptb_urllib3.urllib3.connection.VerifiedHTTPSConnection object at 0x7ff24b23ffd0>: Failed to establish a new connection: [Errno -3] Temporary failure in name resolution')': /bot5019690287:AAH9nfL4sWzLiF5Tuza3Jf_DuqiFJZo8qqI/getUpdates
2022-01-08 11:51:40,805 - telegram.vendor.ptb_urllib3.urllib3.connectionpool - WARNING - Retrying (Retry(total=1, connect=None, read=None, redirect=None)) after connection broken by 'NewConnectionError('<telegram.vendor.ptb_urllib3.urllib3.connection.VerifiedHTTPSConnection object at 0x7ff24b23fdc0>: Failed to establish a new connection: [Errno -3] Temporary failure in name resolution')': /bot5019690287:AAH9nfL4sWzLiF5Tuza3Jf_DuqiFJZo8qqI/getUpdates
2022-01-08 11:51:40,807 - telegram.vendor.ptb_urllib3.urllib3.connectionpool - WARNING - Retrying (Retry(total=0, connect=None, read=None, redirect=None)) after connection broken by 'NewConnectionError('<telegram.vendor.ptb_urllib3.urllib3.connection.VerifiedHTTPSConnection object at 0x7ff24b23f100>: Failed to establish a new connection: [Errno -3] Temporary failure in name resolution')': /bot5019690287:AAH9nfL4sWzLiF5Tuza3Jf_DuqiFJZo8qqI/getUpdates
2022-01-08 11:51:40,809 - telegram.ext.updater - ERROR - Error while getting Updates: urllib3 HTTPError HTTPSConnectionPool(host='api.telegram.org', port=443): Max retries exceeded with url: /bot5019690287:AAH9nfL4sWzLiF5Tuza3Jf_DuqiFJZo8qqI/getUpdates (Caused by NewConnectionError('<telegram.vendor.ptb_urllib3.urllib3.connection.VerifiedHTTPSConnection object at 0x7ff24b23faf0>: Failed to establish a new connection: [Errno -3] Temporary failure in name resolution'))
2022-01-08 11:51:40,810 - __main__ - WARNING - [UPDATE] "None" causa del error "urllib3 HTTPError HTTPSConnectionPool(host='api.telegram.org', port=443): Max retries exceeded with url: /bot5019690287:AAH9nfL4sWzLiF5Tuza3Jf_DuqiFJZo8qqI/getUpdates (Caused by NewConnectionError('<telegram.vendor.ptb_urllib3.urllib3.connection.VerifiedHTTPSConnection object at 0x7ff24b23faf0>: Failed to establish a new connection: [Errno -3] Temporary failure in name resolution'))"
2022-01-08 11:51:41,813 - telegram.vendor.ptb_urllib3.urllib3.connectionpool - WARNING - Retrying (Retry(total=2, connect=None, read=None, redirect=None)) after connection broken by 'NewConnectionError('<telegram.vendor.ptb_urllib3.urllib3.connection.VerifiedHTTPSConnection object at 0x7ff248198130>: Failed to establish a new connection: [Errno -3] Temporary failure in name resolution')': /bot5019690287:AAH9nfL4sWzLiF5Tuza3Jf_DuqiFJZo8qqI/getUpdates
2022-01-08 11:51:41,814 - telegram.vendor.ptb_urllib3.urllib3.connectionpool - WARNING - Retrying (Retry(total=1, connect=None, read=None, redirect=None)) after connection broken by 'NewConnectionError('<telegram.vendor.ptb_urllib3.urllib3.connection.VerifiedHTTPSConnection object at 0x7ff24b228b50>: Failed to establish a new connection: [Errno -3] Temporary failure in name resolution')': /bot5019690287:AAH9nfL4sWzLiF5Tuza3Jf_DuqiFJZo8qqI/getUpdates
2022-01-08 11:51:41,816 - telegram.vendor.ptb_urllib3.urllib3.connectionpool - WARNING - Retrying (Retry(total=0, connect=None, read=None, redirect=None)) after connection broken by 'NewConnectionError('<telegram.vendor.ptb_urllib3.urllib3.connection.VerifiedHTTPSConnection object at 0x7ff2481ac160>: Failed to establish a new connection: [Errno -3] Temporary failure in name resolution')': /bot5019690287:AAH9nfL4sWzLiF5Tuza3Jf_DuqiFJZo8qqI/getUpdates
2022-01-08 11:51:41,818 - telegram.ext.updater - ERROR - Error while getting Updates: urllib3 HTTPError HTTPSConnectionPool(host='api.telegram.org', port=443): Max retries exceeded with url: /bot5019690287:AAH9nfL4sWzLiF5Tuza3Jf_DuqiFJZo8qqI/getUpdates (Caused by NewConnectionError('<telegram.vendor.ptb_urllib3.urllib3.connection.VerifiedHTTPSConnection object at 0x7ff2481ac400>: Failed to establish a new connection: [Errno -3] Temporary failure in name resolution'))
2022-01-08 11:51:41,818 - __main__ - WARNING - [UPDATE] "None" causa del error "urllib3 HTTPError HTTPSConnectionPool(host='api.telegram.org', port=443): Max retries exceeded with url: /bot5019690287:AAH9nfL4sWzLiF5Tuza3Jf_DuqiFJZo8qqI/getUpdates (Caused by NewConnectionError('<telegram.vendor.ptb_urllib3.urllib3.connection.VerifiedHTTPSConnection object at 0x7ff2481ac400>: Failed to establish a new connection: [Errno -3] Temporary failure in name resolution'))"
2022-01-08 11:51:43,322 - telegram.vendor.ptb_urllib3.urllib3.connectionpool - WARNING - Retrying (Retry(total=2, connect=None, read=None, redirect=None)) after connection broken by 'NewConnectionError('<telegram.vendor.ptb_urllib3.urllib3.connection.VerifiedHTTPSConnection object at 0x7ff248198850>: Failed to establish a new connection: [Errno -3] Temporary failure in name resolution')': /bot5019690287:AAH9nfL4sWzLiF5Tuza3Jf_DuqiFJZo8qqI/getUpdates
2022-01-08 11:51:43,324 - telegram.vendor.ptb_urllib3.urllib3.connectionpool - WARNING - Retrying (Retry(total=1, connect=None, read=None, redirect=None)) after connection broken by 'NewConnectionError('<telegram.vendor.ptb_urllib3.urllib3.connection.VerifiedHTTPSConnection object at 0x7ff2481ac640>: Failed to establish a new connection: [Errno -3] Temporary failure in name resolution')': /bot5019690287:AAH9nfL4sWzLiF5Tuza3Jf_DuqiFJZo8qqI/getUpdates
2022-01-08 11:51:43,325 - telegram.vendor.ptb_urllib3.urllib3.connectionpool - WARNING - Retrying (Retry(total=0, connect=None, read=None, redirect=None)) after connection broken by 'NewConnectionError('<telegram.vendor.ptb_urllib3.urllib3.connection.VerifiedHTTPSConnection object at 0x7ff2481ac7c0>: Failed to establish a new connection: [Errno -3] Temporary failure in name resolution')': /bot5019690287:AAH9nfL4sWzLiF5Tuza3Jf_DuqiFJZo8qqI/getUpdates
2022-01-08 11:51:43,328 - telegram.ext.updater - ERROR - Error while getting Updates: urllib3 HTTPError HTTPSConnectionPool(host='api.telegram.org', port=443): Max retries exceeded with url: /bot5019690287:AAH9nfL4sWzLiF5Tuza3Jf_DuqiFJZo8qqI/getUpdates (Caused by NewConnectionError('<telegram.vendor.ptb_urllib3.urllib3.connection.VerifiedHTTPSConnection object at 0x7ff2481ac940>: Failed to establish a new connection: [Errno -3] Temporary failure in name resolution'))
2022-01-08 11:51:43,328 - __main__ - WARNING - [UPDATE] "None" causa del error "urllib3 HTTPError HTTPSConnectionPool(host='api.telegram.org', port=443): Max retries exceeded with url: /bot5019690287:AAH9nfL4sWzLiF5Tuza3Jf_DuqiFJZo8qqI/getUpdates (Caused by NewConnectionError('<telegram.vendor.ptb_urllib3.urllib3.connection.VerifiedHTTPSConnection object at 0x7ff2481ac940>: Failed to establish a new connection: [Errno -3] Temporary failure in name resolution'))"
2022-01-08 11:55:49,602 - telegram.ext.updater - INFO - Received signal 2 (SIGINT), stopping...
2022-01-08 11:55:49,608 - apscheduler.scheduler - INFO - Scheduler has been shut down
2022-01-08 11:55:52,009 - telegram.ext.updater - WARNING - Exiting immediately!
2022-01-08 11:55:54,324 - root - INFO - InfiniemBot Iniciado...
2022-01-08 11:55:54,329 - apscheduler.scheduler - INFO - Scheduler started
2022-01-08 11:56:02,520 - __main__ - WARNING - [UPDATE] "{'message': {'delete_chat_photo': False, 'caption_entities': [], 'entities': [{'offset': 0, 'type': 'bot_command', 'length': 8}], 'new_chat_photo': [], 'date': 1641653763, 'message_id': 377, 'photo': [], 'supergroup_chat_created': False, 'chat': {'type': 'private', 'first_name': 'Max', 'id': 1211957358}, 'new_chat_members': [], 'text': '/mensaje', 'channel_chat_created': False, 'group_chat_created': False, 'from': {'language_code': 'en', 'is_bot': False, 'first_name': 'Max', 'id': 1211957358}}, 'update_id': 197674733}" causa del error "list index out of range"
2022-01-08 11:56:10,287 - __main__ - INFO - [UPDATE] Usuario Max consume el servicio /buscar
2022-01-08 12:07:05,344 - telegram.ext.updater - INFO - Received signal 2 (SIGINT), stopping...
2022-01-08 12:07:05,346 - apscheduler.scheduler - INFO - Scheduler has been shut down
2022-01-08 12:07:07,754 - telegram.ext.updater - WARNING - Exiting immediately!
2022-01-08 12:07:10,183 - root - INFO - InfiniemBot Iniciado...
2022-01-08 12:07:10,191 - apscheduler.scheduler - INFO - Scheduler started
2022-01-08 12:07:27,670 - root - INFO - [NEW ACCESS] chat_id : 1211957358 - firstname : Max - lastname : None - username None
2022-01-08 12:07:30,461 - __main__ - INFO - [UPDATE] Usuario Max consume el servicio /buscar üîé
2022-01-08 12:07:47,443 - __main__ - WARNING - [UPDATE] "{'update_id': 197674739, 'edited_message': {'delete_chat_photo': False, 'entities': [{'offset': 0, 'length': 8, 'type': 'bot_command'}], 'date': 1641654461, 'chat': {'type': 'private', 'id': 1211957358, 'first_name': 'Max'}, 'photo': [], 'new_chat_members': [], 'edit_date': 1641654468, 'channel_chat_created': False, 'message_id': 386, 'group_chat_created': False, 'supergroup_chat_created': False, 'new_chat_photo': [], 'caption_entities': [], 'text': '/mensaje as as', 'from': {'language_code': 'en', 'is_bot': False, 'id': 1211957358, 'first_name': 'Max'}}}" causa del error "'NoneType' object has no attribute 'from_user'"
2022-01-08 12:08:01,857 - __main__ - WARNING - [UPDATE] "{'update_id': 197674740, 'edited_message': {'delete_chat_photo': False, 'entities': [{'offset': 0, 'length': 8, 'type': 'bot_command'}], 'date': 1641654461, 'chat': {'type': 'private', 'id': 1211957358, 'first_name': 'Max'}, 'photo': [], 'new_chat_members': [], 'edit_date': 1641654482, 'channel_chat_created': False, 'message_id': 386, 'group_chat_created': False, 'supergroup_chat_created': False, 'new_chat_photo': [], 'caption_entities': [], 'text': '/mensaje\xa0as as', 'from': {'language_code': 'en', 'is_bot': False, 'id': 1211957358, 'first_name': 'Max'}}}" causa del error "'NoneType' object has no attribute 'from_user'"
2022-01-08 12:08:05,042 - __main__ - WARNING - [UPDATE] "{'update_id': 197674741, 'edited_message': {'delete_chat_photo': False, 'entities': [{'offset': 0, 'length': 8, 'type': 'bot_command'}], 'date': 1641654461, 'chat': {'type': 'private', 'id': 1211957358, 'first_name': 'Max'}, 'photo': [], 'new_chat_members': [], 'edit_date': 1641654486, 'channel_chat_created': False, 'message_id': 386, 'group_chat_created': False, 'supergroup_chat_created': False, 'new_chat_photo': [], 'caption_entities': [], 'text': '/mensaje as', 'from': {'language_code': 'en', 'is_bot': False, 'id': 1211957358, 'first_name': 'Max'}}}" causa del error "'NoneType' object has no attribute 'from_user'"
2022-01-08 12:09:38,597 - telegram.ext.updater - ERROR - Error while getting Updates: Conflict: terminated by other getUpdates request; make sure that only one bot instance is running
2022-01-08 12:09:38,597 - __main__ - WARNING - [UPDATE] "None" causa del error "Conflict: terminated by other getUpdates request; make sure that only one bot instance is running"
2022-01-08 12:12:14,464 - telegram.ext.updater - INFO - Received signal 2 (SIGINT), stopping...
2022-01-08 12:12:14,464 - apscheduler.scheduler - INFO - Scheduler has been shut down
2022-01-08 12:12:14,828 - telegram.ext.updater - WARNING - Exiting immediately!
2022-01-08 12:12:18,904 - root - INFO - InfiniemBot Iniciado...
2022-01-08 12:12:18,908 - apscheduler.scheduler - INFO - Scheduler started
2022-01-08 12:13:41,855 - telegram.ext.updater - INFO - Received signal 2 (SIGINT), stopping...
2022-01-08 12:13:41,856 - apscheduler.scheduler - INFO - Scheduler has been shut down
2022-01-08 12:13:42,097 - telegram.ext.updater - WARNING - Exiting immediately!
2022-01-08 12:13:44,146 - root - INFO - InfiniemBot Iniciado...
2022-01-08 12:13:44,151 - apscheduler.scheduler - INFO - Scheduler started
2022-01-08 12:14:07,173 - telegram.ext.updater - INFO - Received signal 2 (SIGINT), stopping...
2022-01-08 12:14:07,173 - apscheduler.scheduler - INFO - Scheduler has been shut down
2022-01-08 12:14:07,419 - telegram.ext.updater - WARNING - Exiting immediately!
2022-01-08 12:14:11,624 - root - INFO - InfiniemBot Iniciado...
2022-01-08 12:14:11,628 - apscheduler.scheduler - INFO - Scheduler started
2022-01-08 12:15:47,807 - telegram.ext.updater - INFO - Received signal 2 (SIGINT), stopping...
2022-01-08 12:15:47,808 - apscheduler.scheduler - INFO - Scheduler has been shut down
2022-01-08 12:15:48,062 - telegram.ext.updater - WARNING - Exiting immediately!
2022-01-08 12:16:12,446 - root - INFO - InfiniemBot Iniciado...
2022-01-08 12:16:12,450 - apscheduler.scheduler - INFO - Scheduler started
2022-01-08 12:41:41,385 - telegram.ext.updater - ERROR - Error while getting Updates: Conflict: terminated by other getUpdates request; make sure that only one bot instance is running
2022-01-08 12:41:41,387 - __main__ - WARNING - [UPDATE] "None" causa del error "Conflict: terminated by other getUpdates request; make sure that only one bot instance is running"
2022-01-08 12:45:19,163 - telegram.ext.updater - INFO - Received signal 2 (SIGINT), stopping...
2022-01-08 12:45:19,166 - apscheduler.scheduler - INFO - Scheduler has been shut down
2022-01-08 12:45:22,121 - root - INFO - InfiniemBot Iniciado...
2022-01-08 12:45:22,125 - apscheduler.scheduler - INFO - Scheduler started
2022-01-08 12:45:36,512 - root - INFO - [NEW ACCESS] chat_id : 1211957358 - firstname : Max - lastname : None - username None
2022-01-08 12:48:21,739 - telegram.ext.updater - INFO - Received signal 2 (SIGINT), stopping...
2022-01-08 12:48:21,739 - apscheduler.scheduler - INFO - Scheduler has been shut down
2022-01-08 12:48:22,522 - telegram.ext.updater - WARNING - Exiting immediately!
2022-01-08 13:06:09,432 - root - INFO - InfiniemBot Iniciado...
2022-01-08 13:06:09,442 - apscheduler.scheduler - INFO - Scheduler started
2022-01-08 13:22:42,024 - telegram.ext.updater - ERROR - Error while getting Updates: Conflict: terminated by other getUpdates request; make sure that only one bot instance is running
2022-01-08 13:22:42,025 - __main__ - WARNING - [UPDATE] "None" causa del error "Conflict: terminated by other getUpdates request; make sure that only one bot instance is running"
2022-01-08 13:24:17,412 - telegram.ext.updater - INFO - Received signal 2 (SIGINT), stopping...
2022-01-08 13:24:17,413 - apscheduler.scheduler - INFO - Scheduler has been shut down
2022-01-08 13:24:17,740 - telegram.ext.updater - WARNING - Exiting immediately!
2022-01-08 13:24:20,240 - root - INFO - InfiniemBot Iniciado...
2022-01-08 13:24:20,246 - apscheduler.scheduler - INFO - Scheduler started
2022-01-08 13:24:27,995 - __main__ - INFO - [UPDATE] Usuario Max consume el servicio /sensores üå°
2022-01-08 13:24:58,422 - telegram.ext.updater - INFO - Received signal 2 (SIGINT), stopping...
2022-01-08 13:24:58,423 - apscheduler.scheduler - INFO - Scheduler has been shut down
2022-01-08 13:24:58,677 - telegram.ext.updater - WARNING - Exiting immediately!
2022-01-08 13:25:00,570 - root - INFO - InfiniemBot Iniciado...
2022-01-08 13:25:00,578 - apscheduler.scheduler - INFO - Scheduler started
2022-01-08 13:25:02,406 - __main__ - INFO - [UPDATE] Usuario Max consume el servicio /sensores
2022-01-08 13:32:43,632 - __main__ - INFO - [UPDATE] Usuario Max consume el servicio /sensores üå°
2022-01-08 13:52:31,269 - telegram.ext.updater - INFO - Received signal 2 (SIGINT), stopping...
2022-01-08 13:52:31,276 - apscheduler.scheduler - INFO - Scheduler has been shut down
2022-01-08 13:52:32,325 - telegram.ext.updater - WARNING - Exiting immediately!
2022-01-08 13:52:33,950 - root - INFO - InfiniemBot Iniciado...
2022-01-08 13:52:33,955 - apscheduler.scheduler - INFO - Scheduler started
2022-01-08 13:52:47,103 - __main__ - INFO - [UPDATE] Usuario Max consume el servicio /sensores
2022-01-08 13:52:50,052 - __main__ - WARNING - [UPDATE] "{'update_id': 197674762, 'message': {'caption_entities': [], 'new_chat_members': [], 'entities': [{'offset': 0, 'length': 12, 'type': 'bot_command'}], 'text': '/temperatura', 'new_chat_photo': [], 'chat': {'first_name': 'Max', 'type': 'private', 'id': 1211957358}, 'supergroup_chat_created': False, 'date': 1641660769, 'channel_chat_created': False, 'photo': [], 'group_chat_created': False, 'message_id': 428, 'delete_chat_photo': False, 'from': {'language_code': 'en', 'is_bot': False, 'first_name': 'Max', 'id': 1211957358}}}" causa del error "Unsupported parse_mode"
2022-01-08 13:56:53,953 - telegram.ext.updater - INFO - Received signal 2 (SIGINT), stopping...
2022-01-08 13:56:53,954 - apscheduler.scheduler - INFO - Scheduler has been shut down
2022-01-08 13:56:54,725 - telegram.ext.updater - WARNING - Exiting immediately!
2022-01-08 13:56:58,192 - root - INFO - InfiniemBot Iniciado...
2022-01-08 13:56:58,198 - apscheduler.scheduler - INFO - Scheduler started
2022-01-08 13:57:48,718 - __main__ - INFO - [UPDATE] Usuario Max consume el servicio /suerte üçÄ
2022-01-08 13:57:51,833 - __main__ - INFO - [UPDATE] Usuario Max consume el servicio /suerte üçÄ
2022-01-08 14:03:29,125 - telegram.ext.updater - INFO - Received signal 2 (SIGINT), stopping...
2022-01-08 14:03:29,127 - apscheduler.scheduler - INFO - Scheduler has been shut down
2022-01-08 14:03:29,501 - telegram.ext.updater - WARNING - Exiting immediately!
2022-01-08 14:03:31,445 - root - INFO - InfiniemBot Iniciado...
2022-01-08 14:03:31,450 - apscheduler.scheduler - INFO - Scheduler started
2022-01-08 14:03:38,855 - __main__ - WARNING - [UPDATE] "{'message': {'channel_chat_created': False, 'message_id': 435, 'date': 1641661417, 'caption_entities': [], 'chat': {'type': 'private', 'id': 1211957358, 'first_name': 'Max'}, 'supergroup_chat_created': False, 'photo': [], 'new_chat_members': [], 'text': '/temperatura', 'group_chat_created': False, 'entities': [{'type': 'bot_command', 'length': 12, 'offset': 0}], 'new_chat_photo': [], 'delete_chat_photo': False, 'from': {'first_name': 'Max', 'id': 1211957358, 'is_bot': False, 'language_code': 'en'}}, 'update_id': 197674766}" causa del error "'main'"
2022-01-08 14:03:50,595 - __main__ - WARNING - [UPDATE] "{'message': {'channel_chat_created': False, 'message_id': 436, 'date': 1641661429, 'caption_entities': [], 'chat': {'type': 'private', 'id': 1211957358, 'first_name': 'Max'}, 'supergroup_chat_created': False, 'photo': [], 'new_chat_members': [], 'text': '/temperatura', 'group_chat_created': False, 'entities': [{'type': 'bot_command', 'length': 12, 'offset': 0}], 'new_chat_photo': [], 'delete_chat_photo': False, 'from': {'first_name': 'Max', 'id': 1211957358, 'is_bot': False, 'language_code': 'en'}}, 'update_id': 197674767}" causa del error "'main'"
2022-01-08 14:05:11,504 - telegram.ext.updater - INFO - Received signal 2 (SIGINT), stopping...
2022-01-08 14:05:11,504 - apscheduler.scheduler - INFO - Scheduler has been shut down
2022-01-08 14:05:11,830 - telegram.ext.updater - WARNING - Exiting immediately!
2022-01-08 14:05:13,745 - root - INFO - InfiniemBot Iniciado...
2022-01-08 14:05:13,750 - apscheduler.scheduler - INFO - Scheduler started
2022-01-08 14:06:54,624 - telegram.ext.updater - INFO - Received signal 2 (SIGINT), stopping...
2022-01-08 14:06:54,625 - apscheduler.scheduler - INFO - Scheduler has been shut down
2022-01-08 14:06:54,924 - telegram.ext.updater - WARNING - Exiting immediately!
2022-01-08 14:06:56,929 - root - INFO - InfiniemBot Iniciado...
2022-01-08 14:06:56,933 - apscheduler.scheduler - INFO - Scheduler started
2022-01-08 14:13:04,422 - __main__ - INFO - [UPDATE] Usuario Max consume el servicio /sensores üå°
2022-01-08 14:13:34,017 - __main__ - INFO - [UPDATE] Usuario Max consume el servicio /suerte
2022-01-08 14:13:36,110 - __main__ - INFO - [UPDATE] Usuario Max consume el servicio /suerte
2022-01-08 14:17:53,542 - root - INFO - [NEW ACCESS] chat_id : 1211957358 - firstname : Max - lastname : None - username None
2022-01-08 14:17:58,549 - __main__ - WARNING - [UPDATE] "{'message': {'new_chat_members': [], 'date': 1641662273, 'new_chat_photo': [], 'caption_entities': [], 'photo': [], 'channel_chat_created': False, 'message_id': 453, 'group_chat_created': False, 'entities': [{'length': 6, 'offset': 0, 'type': 'bot_command'}], 'chat': {'first_name': 'Max', 'type': 'private', 'id': 1211957358}, 'supergroup_chat_created': False, 'text': '/start', 'delete_chat_photo': False, 'from': {'first_name': 'Max', 'language_code': 'es', 'id': 1211957358, 'is_bot': False}}, 'update_id': 197674776}" causa del error "Timed out"
2022-01-08 14:32:46,896 - telegram.ext.updater - INFO - Received signal 2 (SIGINT), stopping...
2022-01-08 14:32:46,897 - apscheduler.scheduler - INFO - Scheduler has been shut down
2022-01-08 14:32:47,192 - telegram.ext.updater - WARNING - Exiting immediately!
2022-01-08 14:32:50,371 - root - INFO - InfiniemBot Iniciado...
2022-01-08 14:32:50,379 - apscheduler.scheduler - INFO - Scheduler started
2022-01-08 14:32:52,018 - root - INFO - [NEW ACCESS] chat_id : 1211957358 - firstname : Max - lastname : None - username None
2022-01-08 14:33:10,434 - __main__ - INFO - [UPDATE] Usuario Max consume el servicio /buscar üîé
2022-01-08 14:34:37,186 - __main__ - INFO - [UPDATE] Usuario Max consume el servicio /sensores üå°
2022-01-08 14:34:42,193 - __main__ - WARNING - [UPDATE] "{'message': {'date': 1641663277, 'entities': [{'offset': 0, 'type': 'bot_command', 'length': 9}], 'text': '/sensores üå°', 'new_chat_members': [], 'new_chat_photo': [], 'delete_chat_photo': False, 'caption_entities': [], 'chat': {'first_name': 'Max', 'id': 1211957358, 'type': 'private'}, 'message_id': 461, 'channel_chat_created': False, 'supergroup_chat_created': False, 'group_chat_created': False, 'photo': [], 'from': {'first_name': 'Max', 'id': 1211957358, 'is_bot': False, 'language_code': 'en'}}, 'update_id': 197674780}" causa del error "Timed out"
2022-01-08 14:34:45,993 - __main__ - INFO - [UPDATE] Usuario Max consume el servicio /sensores
2022-01-08 14:34:47,778 - __main__ - INFO - [UPDATE] Usuario Max consume el servicio /sensores üå°
2022-01-08 14:34:53,197 - __main__ - INFO - [UPDATE] Usuario Max consume el servicio /sensores üå°
2022-01-08 14:35:09,673 - telegram.ext.updater - ERROR - Error while getting Updates: Conflict: terminated by other getUpdates request; make sure that only one bot instance is running
2022-01-08 14:35:09,674 - __main__ - WARNING - [UPDATE] "None" causa del error "Conflict: terminated by other getUpdates request; make sure that only one bot instance is running"
2022-01-08 14:39:48,249 - telegram.ext.updater - INFO - Received signal 2 (SIGINT), stopping...
2022-01-08 14:39:48,251 - apscheduler.scheduler - INFO - Scheduler has been shut down
2022-01-08 14:39:48,970 - telegram.ext.updater - WARNING - Exiting immediately!
2022-01-08 14:39:50,823 - root - INFO - InfiniemBot Iniciado...
2022-01-08 14:39:50,827 - apscheduler.scheduler - INFO - Scheduler started
2022-01-08 14:39:58,219 - __main__ - INFO - [UPDATE] Usuario Max consume el servicio /sensores
2022-01-08 14:40:00,262 - __main__ - INFO - [UPDATE] Usuario Max consume el servicio /acciones üí°
2022-01-08 14:51:24,118 - telegram.vendor.ptb_urllib3.urllib3.connectionpool - WARNING - Retrying (Retry(total=2, connect=None, read=None, redirect=None)) after connection broken by 'NewConnectionError('<telegram.vendor.ptb_urllib3.urllib3.connection.VerifiedHTTPSConnection object at 0x7f5dcdb20bb0>: Failed to establish a new connection: [Errno -3] Temporary failure in name resolution')': /bot5019690287:AAH9nfL4sWzLiF5Tuza3Jf_DuqiFJZo8qqI/getUpdates
2022-01-08 14:51:24,121 - telegram.vendor.ptb_urllib3.urllib3.connectionpool - WARNING - Retrying (Retry(total=1, connect=None, read=None, redirect=None)) after connection broken by 'NewConnectionError('<telegram.vendor.ptb_urllib3.urllib3.connection.VerifiedHTTPSConnection object at 0x7f5dcdb20dc0>: Failed to establish a new connection: [Errno -3] Temporary failure in name resolution')': /bot5019690287:AAH9nfL4sWzLiF5Tuza3Jf_DuqiFJZo8qqI/getUpdates
2022-01-08 14:51:24,126 - telegram.vendor.ptb_urllib3.urllib3.connectionpool - WARNING - Retrying (Retry(total=0, connect=None, read=None, redirect=None)) after connection broken by 'NewConnectionError('<telegram.vendor.ptb_urllib3.urllib3.connection.VerifiedHTTPSConnection object at 0x7f5dcdb20ee0>: Failed to establish a new connection: [Errno -3] Temporary failure in name resolution')': /bot5019690287:AAH9nfL4sWzLiF5Tuza3Jf_DuqiFJZo8qqI/getUpdates
2022-01-08 14:51:24,132 - telegram.ext.updater - ERROR - Error while getting Updates: urllib3 HTTPError HTTPSConnectionPool(host='api.telegram.org', port=443): Max retries exceeded with url: /bot5019690287:AAH9nfL4sWzLiF5Tuza3Jf_DuqiFJZo8qqI/getUpdates (Caused by NewConnectionError('<telegram.vendor.ptb_urllib3.urllib3.connection.VerifiedHTTPSConnection object at 0x7f5dcc268070>: Failed to establish a new connection: [Errno -3] Temporary failure in name resolution'))
2022-01-08 14:51:24,133 - __main__ - WARNING - [UPDATE] "None" causa del error "urllib3 HTTPError HTTPSConnectionPool(host='api.telegram.org', port=443): Max retries exceeded with url: /bot5019690287:AAH9nfL4sWzLiF5Tuza3Jf_DuqiFJZo8qqI/getUpdates (Caused by NewConnectionError('<telegram.vendor.ptb_urllib3.urllib3.connection.VerifiedHTTPSConnection object at 0x7f5dcc268070>: Failed to establish a new connection: [Errno -3] Temporary failure in name resolution'))"
2022-01-08 14:51:25,137 - telegram.vendor.ptb_urllib3.urllib3.connectionpool - WARNING - Retrying (Retry(total=2, connect=None, read=None, redirect=None)) after connection broken by 'NewConnectionError('<telegram.vendor.ptb_urllib3.urllib3.connection.VerifiedHTTPSConnection object at 0x7f5dcdb20b50>: Failed to establish a new connection: [Errno -3] Temporary failure in name resolution')': /bot5019690287:AAH9nfL4sWzLiF5Tuza3Jf_DuqiFJZo8qqI/getUpdates
2022-01-08 14:51:25,139 - telegram.vendor.ptb_urllib3.urllib3.connectionpool - WARNING - Retrying (Retry(total=1, connect=None, read=None, redirect=None)) after connection broken by 'NewConnectionError('<telegram.vendor.ptb_urllib3.urllib3.connection.VerifiedHTTPSConnection object at 0x7f5dcc268280>: Failed to establish a new connection: [Errno -3] Temporary failure in name resolution')': /bot5019690287:AAH9nfL4sWzLiF5Tuza3Jf_DuqiFJZo8qqI/getUpdates
2022-01-08 14:51:25,142 - telegram.vendor.ptb_urllib3.urllib3.connectionpool - WARNING - Retrying (Retry(total=0, connect=None, read=None, redirect=None)) after connection broken by 'NewConnectionError('<telegram.vendor.ptb_urllib3.urllib3.connection.VerifiedHTTPSConnection object at 0x7f5dcc2683d0>: Failed to establish a new connection: [Errno -3] Temporary failure in name resolution')': /bot5019690287:AAH9nfL4sWzLiF5Tuza3Jf_DuqiFJZo8qqI/getUpdates
2022-01-08 14:51:25,147 - telegram.ext.updater - ERROR - Error while getting Updates: urllib3 HTTPError HTTPSConnectionPool(host='api.telegram.org', port=443): Max retries exceeded with url: /bot5019690287:AAH9nfL4sWzLiF5Tuza3Jf_DuqiFJZo8qqI/getUpdates (Caused by NewConnectionError('<telegram.vendor.ptb_urllib3.urllib3.connection.VerifiedHTTPSConnection object at 0x7f5dcc268520>: Failed to establish a new connection: [Errno -3] Temporary failure in name resolution'))
2022-01-08 14:51:25,149 - __main__ - WARNING - [UPDATE] "None" causa del error "urllib3 HTTPError HTTPSConnectionPool(host='api.telegram.org', port=443): Max retries exceeded with url: /bot5019690287:AAH9nfL4sWzLiF5Tuza3Jf_DuqiFJZo8qqI/getUpdates (Caused by NewConnectionError('<telegram.vendor.ptb_urllib3.urllib3.connection.VerifiedHTTPSConnection object at 0x7f5dcc268520>: Failed to establish a new connection: [Errno -3] Temporary failure in name resolution'))"
2022-01-08 14:51:26,652 - telegram.vendor.ptb_urllib3.urllib3.connectionpool - WARNING - Retrying (Retry(total=2, connect=None, read=None, redirect=None)) after connection broken by 'NewConnectionError('<telegram.vendor.ptb_urllib3.urllib3.connection.VerifiedHTTPSConnection object at 0x7f5dcc268070>: Failed to establish a new connection: [Errno -3] Temporary failure in name resolution')': /bot5019690287:AAH9nfL4sWzLiF5Tuza3Jf_DuqiFJZo8qqI/getUpdates
2022-01-08 14:51:26,654 - telegram.vendor.ptb_urllib3.urllib3.connectionpool - WARNING - Retrying (Retry(total=1, connect=None, read=None, redirect=None)) after connection broken by 'NewConnectionError('<telegram.vendor.ptb_urllib3.urllib3.connection.VerifiedHTTPSConnection object at 0x7f5dcc2686d0>: Failed to establish a new connection: [Errno -3] Temporary failure in name resolution')': /bot5019690287:AAH9nfL4sWzLiF5Tuza3Jf_DuqiFJZo8qqI/getUpdates
2022-01-08 14:51:26,656 - telegram.vendor.ptb_urllib3.urllib3.connectionpool - WARNING - Retrying (Retry(total=0, connect=None, read=None, redirect=None)) after connection broken by 'NewConnectionError('<telegram.vendor.ptb_urllib3.urllib3.connection.VerifiedHTTPSConnection object at 0x7f5dcc268820>: Failed to establish a new connection: [Errno -3] Temporary failure in name resolution')': /bot5019690287:AAH9nfL4sWzLiF5Tuza3Jf_DuqiFJZo8qqI/getUpdates
2022-01-08 14:51:26,657 - telegram.ext.updater - ERROR - Error while getting Updates: urllib3 HTTPError HTTPSConnectionPool(host='api.telegram.org', port=443): Max retries exceeded with url: /bot5019690287:AAH9nfL4sWzLiF5Tuza3Jf_DuqiFJZo8qqI/getUpdates (Caused by NewConnectionError('<telegram.vendor.ptb_urllib3.urllib3.connection.VerifiedHTTPSConnection object at 0x7f5dcc268970>: Failed to establish a new connection: [Errno -3] Temporary failure in name resolution'))
2022-01-08 14:51:26,658 - __main__ - WARNING - [UPDATE] "None" causa del error "urllib3 HTTPError HTTPSConnectionPool(host='api.telegram.org', port=443): Max retries exceeded with url: /bot5019690287:AAH9nfL4sWzLiF5Tuza3Jf_DuqiFJZo8qqI/getUpdates (Caused by NewConnectionError('<telegram.vendor.ptb_urllib3.urllib3.connection.VerifiedHTTPSConnection object at 0x7f5dcc268970>: Failed to establish a new connection: [Errno -3] Temporary failure in name resolution'))"
2022-01-08 14:51:29,700 - __main__ - INFO - [UPDATE] Usuario Max consume el servicio /sensores üå°
2022-01-08 14:51:34,705 - __main__ - WARNING - [UPDATE] "{'message': {'message_id': 475, 'chat': {'first_name': 'Max', 'id': 1211957358, 'type': 'private'}, 'supergroup_chat_created': False, 'date': 1641664048, 'text': '/sensores üå°', 'new_chat_members': [], 'photo': [], 'caption_entities': [], 'entities': [{'offset': 0, 'length': 9, 'type': 'bot_command'}], 'group_chat_created': False, 'new_chat_photo': [], 'channel_chat_created': False, 'delete_chat_photo': False, 'from': {'id': 1211957358, 'first_name': 'Max', 'is_bot': False, 'language_code': 'es'}}, 'update_id': 197674787}" causa del error "Timed out"
2022-01-08 14:51:56,371 - telegram.vendor.ptb_urllib3.urllib3.connectionpool - WARNING - Retrying (Retry(total=2, connect=None, read=None, redirect=None)) after connection broken by 'NewConnectionError('<telegram.vendor.ptb_urllib3.urllib3.connection.VerifiedHTTPSConnection object at 0x7f5dcc268c40>: Failed to establish a new connection: [Errno -3] Temporary failure in name resolution')': /bot5019690287:AAH9nfL4sWzLiF5Tuza3Jf_DuqiFJZo8qqI/getUpdates
2022-01-08 14:51:56,411 - telegram.vendor.ptb_urllib3.urllib3.connectionpool - WARNING - Retrying (Retry(total=1, connect=None, read=None, redirect=None)) after connection broken by 'NewConnectionError('<telegram.vendor.ptb_urllib3.urllib3.connection.VerifiedHTTPSConnection object at 0x7f5dcc268e20>: Failed to establish a new connection: [Errno -3] Temporary failure in name resolution')': /bot5019690287:AAH9nfL4sWzLiF5Tuza3Jf_DuqiFJZo8qqI/getUpdates
2022-01-08 14:51:56,419 - telegram.vendor.ptb_urllib3.urllib3.connectionpool - WARNING - Retrying (Retry(total=0, connect=None, read=None, redirect=None)) after connection broken by 'NewConnectionError('<telegram.vendor.ptb_urllib3.urllib3.connection.VerifiedHTTPSConnection object at 0x7f5dcdb20fd0>: Failed to establish a new connection: [Errno -3] Temporary failure in name resolution')': /bot5019690287:AAH9nfL4sWzLiF5Tuza3Jf_DuqiFJZo8qqI/getUpdates
2022-01-08 14:51:56,422 - telegram.ext.updater - ERROR - Error while getting Updates: urllib3 HTTPError HTTPSConnectionPool(host='api.telegram.org', port=443): Max retries exceeded with url: /bot5019690287:AAH9nfL4sWzLiF5Tuza3Jf_DuqiFJZo8qqI/getUpdates (Caused by NewConnectionError('<telegram.vendor.ptb_urllib3.urllib3.connection.VerifiedHTTPSConnection object at 0x7f5dcdb20190>: Failed to establish a new connection: [Errno -3] Temporary failure in name resolution'))
2022-01-08 14:51:56,423 - __main__ - WARNING - [UPDATE] "None" causa del error "urllib3 HTTPError HTTPSConnectionPool(host='api.telegram.org', port=443): Max retries exceeded with url: /bot5019690287:AAH9nfL4sWzLiF5Tuza3Jf_DuqiFJZo8qqI/getUpdates (Caused by NewConnectionError('<telegram.vendor.ptb_urllib3.urllib3.connection.VerifiedHTTPSConnection object at 0x7f5dcdb20190>: Failed to establish a new connection: [Errno -3] Temporary failure in name resolution'))"
2022-01-08 14:51:57,427 - telegram.vendor.ptb_urllib3.urllib3.connectionpool - WARNING - Retrying (Retry(total=2, connect=None, read=None, redirect=None)) after connection broken by 'NewConnectionError('<telegram.vendor.ptb_urllib3.urllib3.connection.VerifiedHTTPSConnection object at 0x7f5dcdb20bb0>: Failed to establish a new connection: [Errno -3] Temporary failure in name resolution')': /bot5019690287:AAH9nfL4sWzLiF5Tuza3Jf_DuqiFJZo8qqI/getUpdates
2022-01-08 14:51:57,429 - telegram.vendor.ptb_urllib3.urllib3.connectionpool - WARNING - Retrying (Retry(total=1, connect=None, read=None, redirect=None)) after connection broken by 'NewConnectionError('<telegram.vendor.ptb_urllib3.urllib3.connection.VerifiedHTTPSConnection object at 0x7f5dcdb20b20>: Failed to establish a new connection: [Errno -3] Temporary failure in name resolution')': /bot5019690287:AAH9nfL4sWzLiF5Tuza3Jf_DuqiFJZo8qqI/getUpdates
2022-01-08 14:51:57,431 - telegram.vendor.ptb_urllib3.urllib3.connectionpool - WARNING - Retrying (Retry(total=0, connect=None, read=None, redirect=None)) after connection broken by 'NewConnectionError('<telegram.vendor.ptb_urllib3.urllib3.connection.VerifiedHTTPSConnection object at 0x7f5dcdb04a90>: Failed to establish a new connection: [Errno -3] Temporary failure in name resolution')': /bot5019690287:AAH9nfL4sWzLiF5Tuza3Jf_DuqiFJZo8qqI/getUpdates
2022-01-08 14:51:57,435 - telegram.ext.updater - ERROR - Error while getting Updates: urllib3 HTTPError HTTPSConnectionPool(host='api.telegram.org', port=443): Max retries exceeded with url: /bot5019690287:AAH9nfL4sWzLiF5Tuza3Jf_DuqiFJZo8qqI/getUpdates (Caused by NewConnectionError('<telegram.vendor.ptb_urllib3.urllib3.connection.VerifiedHTTPSConnection object at 0x7f5dcc268af0>: Failed to establish a new connection: [Errno -3] Temporary failure in name resolution'))
2022-01-08 14:51:57,435 - __main__ - WARNING - [UPDATE] "None" causa del error "urllib3 HTTPError HTTPSConnectionPool(host='api.telegram.org', port=443): Max retries exceeded with url: /bot5019690287:AAH9nfL4sWzLiF5Tuza3Jf_DuqiFJZo8qqI/getUpdates (Caused by NewConnectionError('<telegram.vendor.ptb_urllib3.urllib3.connection.VerifiedHTTPSConnection object at 0x7f5dcc268af0>: Failed to establish a new connection: [Errno -3] Temporary failure in name resolution'))"
2022-01-08 14:51:58,938 - telegram.vendor.ptb_urllib3.urllib3.connectionpool - WARNING - Retrying (Retry(total=2, connect=None, read=None, redirect=None)) after connection broken by 'NewConnectionError('<telegram.vendor.ptb_urllib3.urllib3.connection.VerifiedHTTPSConnection object at 0x7f5dcdb20ac0>: Failed to establish a new connection: [Errno -3] Temporary failure in name resolution')': /bot5019690287:AAH9nfL4sWzLiF5Tuza3Jf_DuqiFJZo8qqI/getUpdates
2022-01-08 14:51:58,940 - telegram.vendor.ptb_urllib3.urllib3.connectionpool - WARNING - Retrying (Retry(total=1, connect=None, read=None, redirect=None)) after connection broken by 'NewConnectionError('<telegram.vendor.ptb_urllib3.urllib3.connection.VerifiedHTTPSConnection object at 0x7f5dcc268b80>: Failed to establish a new connection: [Errno -3] Temporary failure in name resolution')': /bot5019690287:AAH9nfL4sWzLiF5Tuza3Jf_DuqiFJZo8qqI/getUpdates
2022-01-08 14:51:58,942 - telegram.vendor.ptb_urllib3.urllib3.connectionpool - WARNING - Retrying (Retry(total=0, connect=None, read=None, redirect=None)) after connection broken by 'NewConnectionError('<telegram.vendor.ptb_urllib3.urllib3.connection.VerifiedHTTPSConnection object at 0x7f5dcc268640>: Failed to establish a new connection: [Errno -3] Temporary failure in name resolution')': /bot5019690287:AAH9nfL4sWzLiF5Tuza3Jf_DuqiFJZo8qqI/getUpdates
2022-01-08 14:51:58,944 - telegram.ext.updater - ERROR - Error while getting Updates: urllib3 HTTPError HTTPSConnectionPool(host='api.telegram.org', port=443): Max retries exceeded with url: /bot5019690287:AAH9nfL4sWzLiF5Tuza3Jf_DuqiFJZo8qqI/getUpdates (Caused by NewConnectionError('<telegram.vendor.ptb_urllib3.urllib3.connection.VerifiedHTTPSConnection object at 0x7f5dcc268cd0>: Failed to establish a new connection: [Errno -3] Temporary failure in name resolution'))
2022-01-08 14:51:58,945 - __main__ - WARNING - [UPDATE] "None" causa del error "urllib3 HTTPError HTTPSConnectionPool(host='api.telegram.org', port=443): Max retries exceeded with url: /bot5019690287:AAH9nfL4sWzLiF5Tuza3Jf_DuqiFJZo8qqI/getUpdates (Caused by NewConnectionError('<telegram.vendor.ptb_urllib3.urllib3.connection.VerifiedHTTPSConnection object at 0x7f5dcc268cd0>: Failed to establish a new connection: [Errno -3] Temporary failure in name resolution'))"
2022-01-08 18:54:31,809 - telegram.vendor.ptb_urllib3.urllib3.connectionpool - WARNING - Retrying (Retry(total=2, connect=None, read=None, redirect=None)) after connection broken by 'NewConnectionError('<telegram.vendor.ptb_urllib3.urllib3.connection.VerifiedHTTPSConnection object at 0x7f5dcc268af0>: Failed to establish a new connection: [Errno -3] Temporary failure in name resolution')': /bot5019690287:AAH9nfL4sWzLiF5Tuza3Jf_DuqiFJZo8qqI/getUpdates
2022-01-08 18:54:31,813 - telegram.vendor.ptb_urllib3.urllib3.connectionpool - WARNING - Retrying (Retry(total=1, connect=None, read=None, redirect=None)) after connection broken by 'NewConnectionError('<telegram.vendor.ptb_urllib3.urllib3.connection.VerifiedHTTPSConnection object at 0x7f5dcc268760>: Failed to establish a new connection: [Errno -3] Temporary failure in name resolution')': /bot5019690287:AAH9nfL4sWzLiF5Tuza3Jf_DuqiFJZo8qqI/getUpdates
2022-01-08 18:54:31,817 - telegram.vendor.ptb_urllib3.urllib3.connectionpool - WARNING - Retrying (Retry(total=0, connect=None, read=None, redirect=None)) after connection broken by 'NewConnectionError('<telegram.vendor.ptb_urllib3.urllib3.connection.VerifiedHTTPSConnection object at 0x7f5dcc2682b0>: Failed to establish a new connection: [Errno -3] Temporary failure in name resolution')': /bot5019690287:AAH9nfL4sWzLiF5Tuza3Jf_DuqiFJZo8qqI/getUpdates
2022-01-08 18:54:31,824 - telegram.ext.updater - ERROR - Error while getting Updates: urllib3 HTTPError HTTPSConnectionPool(host='api.telegram.org', port=443): Max retries exceeded with url: /bot5019690287:AAH9nfL4sWzLiF5Tuza3Jf_DuqiFJZo8qqI/getUpdates (Caused by NewConnectionError('<telegram.vendor.ptb_urllib3.urllib3.connection.VerifiedHTTPSConnection object at 0x7f5dcc268f70>: Failed to establish a new connection: [Errno -3] Temporary failure in name resolution'))
2022-01-08 18:54:31,825 - __main__ - WARNING - [UPDATE] "None" causa del error "urllib3 HTTPError HTTPSConnectionPool(host='api.telegram.org', port=443): Max retries exceeded with url: /bot5019690287:AAH9nfL4sWzLiF5Tuza3Jf_DuqiFJZo8qqI/getUpdates (Caused by NewConnectionError('<telegram.vendor.ptb_urllib3.urllib3.connection.VerifiedHTTPSConnection object at 0x7f5dcc268f70>: Failed to establish a new connection: [Errno -3] Temporary failure in name resolution'))"
2022-01-08 18:54:32,829 - telegram.vendor.ptb_urllib3.urllib3.connectionpool - WARNING - Retrying (Retry(total=2, connect=None, read=None, redirect=None)) after connection broken by 'NewConnectionError('<telegram.vendor.ptb_urllib3.urllib3.connection.VerifiedHTTPSConnection object at 0x7f5dcc268640>: Failed to establish a new connection: [Errno -3] Temporary failure in name resolution')': /bot5019690287:AAH9nfL4sWzLiF5Tuza3Jf_DuqiFJZo8qqI/getUpdates
2022-01-08 18:54:32,831 - telegram.vendor.ptb_urllib3.urllib3.connectionpool - WARNING - Retrying (Retry(total=1, connect=None, read=None, redirect=None)) after connection broken by 'NewConnectionError('<telegram.vendor.ptb_urllib3.urllib3.connection.VerifiedHTTPSConnection object at 0x7f5dcc2685b0>: Failed to establish a new connection: [Errno -3] Temporary failure in name resolution')': /bot5019690287:AAH9nfL4sWzLiF5Tuza3Jf_DuqiFJZo8qqI/getUpdates
2022-01-08 18:54:32,834 - telegram.vendor.ptb_urllib3.urllib3.connectionpool - WARNING - Retrying (Retry(total=0, connect=None, read=None, redirect=None)) after connection broken by 'NewConnectionError('<telegram.vendor.ptb_urllib3.urllib3.connection.VerifiedHTTPSConnection object at 0x7f5dcdb04a90>: Failed to establish a new connection: [Errno -3] Temporary failure in name resolution')': /bot5019690287:AAH9nfL4sWzLiF5Tuza3Jf_DuqiFJZo8qqI/getUpdates
2022-01-08 18:54:32,838 - telegram.ext.updater - ERROR - Error while getting Updates: urllib3 HTTPError HTTPSConnectionPool(host='api.telegram.org', port=443): Max retries exceeded with url: /bot5019690287:AAH9nfL4sWzLiF5Tuza3Jf_DuqiFJZo8qqI/getUpdates (Caused by NewConnectionError('<telegram.vendor.ptb_urllib3.urllib3.connection.VerifiedHTTPSConnection object at 0x7f5dcdb20f70>: Failed to establish a new connection: [Errno -3] Temporary failure in name resolution'))
2022-01-08 18:54:32,838 - __main__ - WARNING - [UPDATE] "None" causa del error "urllib3 HTTPError HTTPSConnectionPool(host='api.telegram.org', port=443): Max retries exceeded with url: /bot5019690287:AAH9nfL4sWzLiF5Tuza3Jf_DuqiFJZo8qqI/getUpdates (Caused by NewConnectionError('<telegram.vendor.ptb_urllib3.urllib3.connection.VerifiedHTTPSConnection object at 0x7f5dcdb20f70>: Failed to establish a new connection: [Errno -3] Temporary failure in name resolution'))"
2022-01-08 18:54:34,341 - telegram.vendor.ptb_urllib3.urllib3.connectionpool - WARNING - Retrying (Retry(total=2, connect=None, read=None, redirect=None)) after connection broken by 'NewConnectionError('<telegram.vendor.ptb_urllib3.urllib3.connection.VerifiedHTTPSConnection object at 0x7f5dcc2687f0>: Failed to establish a new connection: [Errno -3] Temporary failure in name resolution')': /bot5019690287:AAH9nfL4sWzLiF5Tuza3Jf_DuqiFJZo8qqI/getUpdates
2022-01-08 18:54:34,344 - telegram.vendor.ptb_urllib3.urllib3.connectionpool - WARNING - Retrying (Retry(total=1, connect=None, read=None, redirect=None)) after connection broken by 'NewConnectionError('<telegram.vendor.ptb_urllib3.urllib3.connection.VerifiedHTTPSConnection object at 0x7f5dcdb20d60>: Failed to establish a new connection: [Errno -3] Temporary failure in name resolution')': /bot5019690287:AAH9nfL4sWzLiF5Tuza3Jf_DuqiFJZo8qqI/getUpdates
2022-01-08 18:54:34,346 - telegram.vendor.ptb_urllib3.urllib3.connectionpool - WARNING - Retrying (Retry(total=0, connect=None, read=None, redirect=None)) after connection broken by 'NewConnectionError('<telegram.vendor.ptb_urllib3.urllib3.connection.VerifiedHTTPSConnection object at 0x7f5dcdb20c10>: Failed to establish a new connection: [Errno -3] Temporary failure in name resolution')': /bot5019690287:AAH9nfL4sWzLiF5Tuza3Jf_DuqiFJZo8qqI/getUpdates
2022-01-08 18:54:34,348 - telegram.ext.updater - ERROR - Error while getting Updates: urllib3 HTTPError HTTPSConnectionPool(host='api.telegram.org', port=443): Max retries exceeded with url: /bot5019690287:AAH9nfL4sWzLiF5Tuza3Jf_DuqiFJZo8qqI/getUpdates (Caused by NewConnectionError('<telegram.vendor.ptb_urllib3.urllib3.connection.VerifiedHTTPSConnection object at 0x7f5dcdb20130>: Failed to establish a new connection: [Errno -3] Temporary failure in name resolution'))
2022-01-08 18:54:34,348 - __main__ - WARNING - [UPDATE] "None" causa del error "urllib3 HTTPError HTTPSConnectionPool(host='api.telegram.org', port=443): Max retries exceeded with url: /bot5019690287:AAH9nfL4sWzLiF5Tuza3Jf_DuqiFJZo8qqI/getUpdates (Caused by NewConnectionError('<telegram.vendor.ptb_urllib3.urllib3.connection.VerifiedHTTPSConnection object at 0x7f5dcdb20130>: Failed to establish a new connection: [Errno -3] Temporary failure in name resolution'))"
2022-01-08 19:46:22,482 - telegram.vendor.ptb_urllib3.urllib3.connectionpool - WARNING - Retrying (Retry(total=2, connect=None, read=None, redirect=None)) after connection broken by 'NewConnectionError('<telegram.vendor.ptb_urllib3.urllib3.connection.VerifiedHTTPSConnection object at 0x7f5dcc27efa0>: Failed to establish a new connection: [Errno -3] Temporary failure in name resolution')': /bot5019690287:AAH9nfL4sWzLiF5Tuza3Jf_DuqiFJZo8qqI/getUpdates
2022-01-08 19:46:22,484 - telegram.vendor.ptb_urllib3.urllib3.connectionpool - WARNING - Retrying (Retry(total=1, connect=None, read=None, redirect=None)) after connection broken by 'NewConnectionError('<telegram.vendor.ptb_urllib3.urllib3.connection.VerifiedHTTPSConnection object at 0x7f5dcc21c070>: Failed to establish a new connection: [Errno -3] Temporary failure in name resolution')': /bot5019690287:AAH9nfL4sWzLiF5Tuza3Jf_DuqiFJZo8qqI/getUpdates
2022-01-08 19:46:22,486 - telegram.vendor.ptb_urllib3.urllib3.connectionpool - WARNING - Retrying (Retry(total=0, connect=None, read=None, redirect=None)) after connection broken by 'NewConnectionError('<telegram.vendor.ptb_urllib3.urllib3.connection.VerifiedHTTPSConnection object at 0x7f5dcc21c1c0>: Failed to establish a new connection: [Errno -3] Temporary failure in name resolution')': /bot5019690287:AAH9nfL4sWzLiF5Tuza3Jf_DuqiFJZo8qqI/getUpdates
2022-01-08 19:46:22,494 - telegram.ext.updater - ERROR - Error while getting Updates: urllib3 HTTPError HTTPSConnectionPool(host='api.telegram.org', port=443): Max retries exceeded with url: /bot5019690287:AAH9nfL4sWzLiF5Tuza3Jf_DuqiFJZo8qqI/getUpdates (Caused by NewConnectionError('<telegram.vendor.ptb_urllib3.urllib3.connection.VerifiedHTTPSConnection object at 0x7f5dcc21c310>: Failed to establish a new connection: [Errno -3] Temporary failure in name resolution'))
2022-01-08 19:46:22,496 - __main__ - WARNING - [UPDATE] "None" causa del error "urllib3 HTTPError HTTPSConnectionPool(host='api.telegram.org', port=443): Max retries exceeded with url: /bot5019690287:AAH9nfL4sWzLiF5Tuza3Jf_DuqiFJZo8qqI/getUpdates (Caused by NewConnectionError('<telegram.vendor.ptb_urllib3.urllib3.connection.VerifiedHTTPSConnection object at 0x7f5dcc21c310>: Failed to establish a new connection: [Errno -3] Temporary failure in name resolution'))"
2022-01-08 19:46:23,499 - telegram.vendor.ptb_urllib3.urllib3.connectionpool - WARNING - Retrying (Retry(total=2, connect=None, read=None, redirect=None)) after connection broken by 'NewConnectionError('<telegram.vendor.ptb_urllib3.urllib3.connection.VerifiedHTTPSConnection object at 0x7f5dcc2685e0>: Failed to establish a new connection: [Errno -3] Temporary failure in name resolution')': /bot5019690287:AAH9nfL4sWzLiF5Tuza3Jf_DuqiFJZo8qqI/getUpdates
2022-01-08 19:46:23,501 - telegram.vendor.ptb_urllib3.urllib3.connectionpool - WARNING - Retrying (Retry(total=1, connect=None, read=None, redirect=None)) after connection broken by 'NewConnectionError('<telegram.vendor.ptb_urllib3.urllib3.connection.VerifiedHTTPSConnection object at 0x7f5dcc268550>: Failed to establish a new connection: [Errno -3] Temporary failure in name resolution')': /bot5019690287:AAH9nfL4sWzLiF5Tuza3Jf_DuqiFJZo8qqI/getUpdates
2022-01-08 19:46:23,504 - telegram.vendor.ptb_urllib3.urllib3.connectionpool - WARNING - Retrying (Retry(total=0, connect=None, read=None, redirect=None)) after connection broken by 'NewConnectionError('<telegram.vendor.ptb_urllib3.urllib3.connection.VerifiedHTTPSConnection object at 0x7f5dcc268520>: Failed to establish a new connection: [Errno -3] Temporary failure in name resolution')': /bot5019690287:AAH9nfL4sWzLiF5Tuza3Jf_DuqiFJZo8qqI/getUpdates
2022-01-08 19:46:23,508 - telegram.ext.updater - ERROR - Error while getting Updates: urllib3 HTTPError HTTPSConnectionPool(host='api.telegram.org', port=443): Max retries exceeded with url: /bot5019690287:AAH9nfL4sWzLiF5Tuza3Jf_DuqiFJZo8qqI/getUpdates (Caused by NewConnectionError('<telegram.vendor.ptb_urllib3.urllib3.connection.VerifiedHTTPSConnection object at 0x7f5dcc268490>: Failed to establish a new connection: [Errno -3] Temporary failure in name resolution'))
2022-01-08 19:46:23,508 - __main__ - WARNING - [UPDATE] "None" causa del error "urllib3 HTTPError HTTPSConnectionPool(host='api.telegram.org', port=443): Max retries exceeded with url: /bot5019690287:AAH9nfL4sWzLiF5Tuza3Jf_DuqiFJZo8qqI/getUpdates (Caused by NewConnectionError('<telegram.vendor.ptb_urllib3.urllib3.connection.VerifiedHTTPSConnection object at 0x7f5dcc268490>: Failed to establish a new connection: [Errno -3] Temporary failure in name resolution'))"
2022-01-09 08:20:35,172 - __main__ - WARNING - [UPDATE] "{'message': {'message_id': 479, 'chat': {'first_name': 'Max', 'id': 1211957358, 'type': 'private'}, 'supergroup_chat_created': False, 'date': 1641688354, 'text': '/hambiente', 'new_chat_members': [], 'photo': [], 'caption_entities': [], 'entities': [{'offset': 0, 'length': 10, 'type': 'bot_command'}], 'group_chat_created': False, 'new_chat_photo': [], 'channel_chat_created': False, 'delete_chat_photo': False, 'from': {'id': 1211957358, 'first_name': 'Max', 'is_bot': False, 'language_code': 'es'}}, 'update_id': 197674789}" causa del error "Timed out"
2022-01-09 08:20:35,173 - __main__ - INFO - [UPDATE] Usuario Max consume el servicio /acciones üí°
2022-01-09 08:25:09,357 - telegram.vendor.ptb_urllib3.urllib3.connectionpool - WARNING - Retrying (Retry(total=2, connect=None, read=None, redirect=None)) after connection broken by 'NewConnectionError('<telegram.vendor.ptb_urllib3.urllib3.connection.VerifiedHTTPSConnection object at 0x7f5dcc27ef10>: Failed to establish a new connection: [Errno -3] Temporary failure in name resolution')': /bot5019690287:AAH9nfL4sWzLiF5Tuza3Jf_DuqiFJZo8qqI/getUpdates
2022-01-09 08:25:09,359 - telegram.vendor.ptb_urllib3.urllib3.connectionpool - WARNING - Retrying (Retry(total=1, connect=None, read=None, redirect=None)) after connection broken by 'NewConnectionError('<telegram.vendor.ptb_urllib3.urllib3.connection.VerifiedHTTPSConnection object at 0x7f5dcc21c850>: Failed to establish a new connection: [Errno -3] Temporary failure in name resolution')': /bot5019690287:AAH9nfL4sWzLiF5Tuza3Jf_DuqiFJZo8qqI/getUpdates
2022-01-09 08:25:09,361 - telegram.vendor.ptb_urllib3.urllib3.connectionpool - WARNING - Retrying (Retry(total=0, connect=None, read=None, redirect=None)) after connection broken by 'NewConnectionError('<telegram.vendor.ptb_urllib3.urllib3.connection.VerifiedHTTPSConnection object at 0x7f5dcc21c8e0>: Failed to establish a new connection: [Errno -3] Temporary failure in name resolution')': /bot5019690287:AAH9nfL4sWzLiF5Tuza3Jf_DuqiFJZo8qqI/getUpdates
2022-01-09 08:25:09,362 - telegram.ext.updater - ERROR - Error while getting Updates: urllib3 HTTPError HTTPSConnectionPool(host='api.telegram.org', port=443): Max retries exceeded with url: /bot5019690287:AAH9nfL4sWzLiF5Tuza3Jf_DuqiFJZo8qqI/getUpdates (Caused by NewConnectionError('<telegram.vendor.ptb_urllib3.urllib3.connection.VerifiedHTTPSConnection object at 0x7f5dcc21ca30>: Failed to establish a new connection: [Errno -3] Temporary failure in name resolution'))
2022-01-09 08:25:09,363 - __main__ - WARNING - [UPDATE] "None" causa del error "urllib3 HTTPError HTTPSConnectionPool(host='api.telegram.org', port=443): Max retries exceeded with url: /bot5019690287:AAH9nfL4sWzLiF5Tuza3Jf_DuqiFJZo8qqI/getUpdates (Caused by NewConnectionError('<telegram.vendor.ptb_urllib3.urllib3.connection.VerifiedHTTPSConnection object at 0x7f5dcc21ca30>: Failed to establish a new connection: [Errno -3] Temporary failure in name resolution'))"
2022-01-09 08:25:10,366 - telegram.vendor.ptb_urllib3.urllib3.connectionpool - WARNING - Retrying (Retry(total=2, connect=None, read=None, redirect=None)) after connection broken by 'NewConnectionError('<telegram.vendor.ptb_urllib3.urllib3.connection.VerifiedHTTPSConnection object at 0x7f5dcdb20040>: Failed to establish a new connection: [Errno -3] Temporary failure in name resolution')': /bot5019690287:AAH9nfL4sWzLiF5Tuza3Jf_DuqiFJZo8qqI/getUpdates
2022-01-09 08:25:10,368 - telegram.vendor.ptb_urllib3.urllib3.connectionpool - WARNING - Retrying (Retry(total=1, connect=None, read=None, redirect=None)) after connection broken by 'NewConnectionError('<telegram.vendor.ptb_urllib3.urllib3.connection.VerifiedHTTPSConnection object at 0x7f5dcc21cc40>: Failed to establish a new connection: [Errno -3] Temporary failure in name resolution')': /bot5019690287:AAH9nfL4sWzLiF5Tuza3Jf_DuqiFJZo8qqI/getUpdates
2022-01-09 08:25:10,369 - telegram.vendor.ptb_urllib3.urllib3.connectionpool - WARNING - Retrying (Retry(total=0, connect=None, read=None, redirect=None)) after connection broken by 'NewConnectionError('<telegram.vendor.ptb_urllib3.urllib3.connection.VerifiedHTTPSConnection object at 0x7f5dcc21cd90>: Failed to establish a new connection: [Errno -3] Temporary failure in name resolution')': /bot5019690287:AAH9nfL4sWzLiF5Tuza3Jf_DuqiFJZo8qqI/getUpdates
2022-01-09 08:25:10,372 - telegram.ext.updater - ERROR - Error while getting Updates: urllib3 HTTPError HTTPSConnectionPool(host='api.telegram.org', port=443): Max retries exceeded with url: /bot5019690287:AAH9nfL4sWzLiF5Tuza3Jf_DuqiFJZo8qqI/getUpdates (Caused by NewConnectionError('<telegram.vendor.ptb_urllib3.urllib3.connection.VerifiedHTTPSConnection object at 0x7f5dcc21cee0>: Failed to establish a new connection: [Errno -3] Temporary failure in name resolution'))
2022-01-09 08:25:10,372 - __main__ - WARNING - [UPDATE] "None" causa del error "urllib3 HTTPError HTTPSConnectionPool(host='api.telegram.org', port=443): Max retries exceeded with url: /bot5019690287:AAH9nfL4sWzLiF5Tuza3Jf_DuqiFJZo8qqI/getUpdates (Caused by NewConnectionError('<telegram.vendor.ptb_urllib3.urllib3.connection.VerifiedHTTPSConnection object at 0x7f5dcc21cee0>: Failed to establish a new connection: [Errno -3] Temporary failure in name resolution'))"
2022-01-09 08:25:11,876 - telegram.vendor.ptb_urllib3.urllib3.connectionpool - WARNING - Retrying (Retry(total=2, connect=None, read=None, redirect=None)) after connection broken by 'NewConnectionError('<telegram.vendor.ptb_urllib3.urllib3.connection.VerifiedHTTPSConnection object at 0x7f5dcc2680a0>: Failed to establish a new connection: [Errno -3] Temporary failure in name resolution')': /bot5019690287:AAH9nfL4sWzLiF5Tuza3Jf_DuqiFJZo8qqI/getUpdates
2022-01-09 08:25:11,879 - telegram.vendor.ptb_urllib3.urllib3.connectionpool - WARNING - Retrying (Retry(total=1, connect=None, read=None, redirect=None)) after connection broken by 'NewConnectionError('<telegram.vendor.ptb_urllib3.urllib3.connection.VerifiedHTTPSConnection object at 0x7f5dcc22d100>: Failed to establish a new connection: [Errno -3] Temporary failure in name resolution')': /bot5019690287:AAH9nfL4sWzLiF5Tuza3Jf_DuqiFJZo8qqI/getUpdates
2022-01-09 08:25:11,882 - telegram.vendor.ptb_urllib3.urllib3.connectionpool - WARNING - Retrying (Retry(total=0, connect=None, read=None, redirect=None)) after connection broken by 'NewConnectionError('<telegram.vendor.ptb_urllib3.urllib3.connection.VerifiedHTTPSConnection object at 0x7f5dcc22d280>: Failed to establish a new connection: [Errno -3] Temporary failure in name resolution')': /bot5019690287:AAH9nfL4sWzLiF5Tuza3Jf_DuqiFJZo8qqI/getUpdates
2022-01-09 08:25:11,892 - telegram.ext.updater - ERROR - Error while getting Updates: urllib3 HTTPError HTTPSConnectionPool(host='api.telegram.org', port=443): Max retries exceeded with url: /bot5019690287:AAH9nfL4sWzLiF5Tuza3Jf_DuqiFJZo8qqI/getUpdates (Caused by NewConnectionError('<telegram.vendor.ptb_urllib3.urllib3.connection.VerifiedHTTPSConnection object at 0x7f5dcc22d400>: Failed to establish a new connection: [Errno -3] Temporary failure in name resolution'))
2022-01-09 08:25:11,894 - __main__ - WARNING - [UPDATE] "None" causa del error "urllib3 HTTPError HTTPSConnectionPool(host='api.telegram.org', port=443): Max retries exceeded with url: /bot5019690287:AAH9nfL4sWzLiF5Tuza3Jf_DuqiFJZo8qqI/getUpdates (Caused by NewConnectionError('<telegram.vendor.ptb_urllib3.urllib3.connection.VerifiedHTTPSConnection object at 0x7f5dcc22d400>: Failed to establish a new connection: [Errno -3] Temporary failure in name resolution'))"
2022-01-09 13:38:54,202 - telegram.vendor.ptb_urllib3.urllib3.connectionpool - WARNING - Retrying (Retry(total=2, connect=None, read=None, redirect=None)) after connection broken by 'NewConnectionError('<telegram.vendor.ptb_urllib3.urllib3.connection.VerifiedHTTPSConnection object at 0x7f5dcc21cee0>: Failed to establish a new connection: [Errno -3] Temporary failure in name resolution')': /bot5019690287:AAH9nfL4sWzLiF5Tuza3Jf_DuqiFJZo8qqI/getUpdates
2022-01-09 13:38:54,205 - telegram.vendor.ptb_urllib3.urllib3.connectionpool - WARNING - Retrying (Retry(total=1, connect=None, read=None, redirect=None)) after connection broken by 'NewConnectionError('<telegram.vendor.ptb_urllib3.urllib3.connection.VerifiedHTTPSConnection object at 0x7f5dcc21caf0>: Failed to establish a new connection: [Errno -3] Temporary failure in name resolution')': /bot5019690287:AAH9nfL4sWzLiF5Tuza3Jf_DuqiFJZo8qqI/getUpdates
2022-01-09 13:38:54,207 - telegram.vendor.ptb_urllib3.urllib3.connectionpool - WARNING - Retrying (Retry(total=0, connect=None, read=None, redirect=None)) after connection broken by 'NewConnectionError('<telegram.vendor.ptb_urllib3.urllib3.connection.VerifiedHTTPSConnection object at 0x7f5dcc21c970>: Failed to establish a new connection: [Errno -3] Temporary failure in name resolution')': /bot5019690287:AAH9nfL4sWzLiF5Tuza3Jf_DuqiFJZo8qqI/getUpdates
2022-01-09 13:38:54,209 - telegram.ext.updater - ERROR - Error while getting Updates: urllib3 HTTPError HTTPSConnectionPool(host='api.telegram.org', port=443): Max retries exceeded with url: /bot5019690287:AAH9nfL4sWzLiF5Tuza3Jf_DuqiFJZo8qqI/getUpdates (Caused by NewConnectionError('<telegram.vendor.ptb_urllib3.urllib3.connection.VerifiedHTTPSConnection object at 0x7f5dcc21c850>: Failed to establish a new connection: [Errno -3] Temporary failure in name resolution'))
2022-01-09 13:38:54,209 - __main__ - WARNING - [UPDATE] "None" causa del error "urllib3 HTTPError HTTPSConnectionPool(host='api.telegram.org', port=443): Max retries exceeded with url: /bot5019690287:AAH9nfL4sWzLiF5Tuza3Jf_DuqiFJZo8qqI/getUpdates (Caused by NewConnectionError('<telegram.vendor.ptb_urllib3.urllib3.connection.VerifiedHTTPSConnection object at 0x7f5dcc21c850>: Failed to establish a new connection: [Errno -3] Temporary failure in name resolution'))"
2022-01-10 05:31:08,092 - telegram.vendor.ptb_urllib3.urllib3.connectionpool - WARNING - Retrying (Retry(total=2, connect=None, read=None, redirect=None)) after connection broken by 'NewConnectionError('<telegram.vendor.ptb_urllib3.urllib3.connection.VerifiedHTTPSConnection object at 0x7f5dcc21c370>: Failed to establish a new connection: [Errno -3] Temporary failure in name resolution')': /bot5019690287:AAH9nfL4sWzLiF5Tuza3Jf_DuqiFJZo8qqI/getUpdates
2022-01-10 05:31:08,099 - telegram.vendor.ptb_urllib3.urllib3.connectionpool - WARNING - Retrying (Retry(total=1, connect=None, read=None, redirect=None)) after connection broken by 'NewConnectionError('<telegram.vendor.ptb_urllib3.urllib3.connection.VerifiedHTTPSConnection object at 0x7f5dcc27e940>: Failed to establish a new connection: [Errno -3] Temporary failure in name resolution')': /bot5019690287:AAH9nfL4sWzLiF5Tuza3Jf_DuqiFJZo8qqI/getUpdates
2022-01-10 05:31:08,106 - telegram.vendor.ptb_urllib3.urllib3.connectionpool - WARNING - Retrying (Retry(total=0, connect=None, read=None, redirect=None)) after connection broken by 'NewConnectionError('<telegram.vendor.ptb_urllib3.urllib3.connection.VerifiedHTTPSConnection object at 0x7f5dcc27e100>: Failed to establish a new connection: [Errno -3] Temporary failure in name resolution')': /bot5019690287:AAH9nfL4sWzLiF5Tuza3Jf_DuqiFJZo8qqI/getUpdates
2022-01-10 05:31:08,116 - telegram.ext.updater - ERROR - Error while getting Updates: urllib3 HTTPError HTTPSConnectionPool(host='api.telegram.org', port=443): Max retries exceeded with url: /bot5019690287:AAH9nfL4sWzLiF5Tuza3Jf_DuqiFJZo8qqI/getUpdates (Caused by NewConnectionError('<telegram.vendor.ptb_urllib3.urllib3.connection.VerifiedHTTPSConnection object at 0x7f5dcc268220>: Failed to establish a new connection: [Errno -3] Temporary failure in name resolution'))
2022-01-10 05:31:08,117 - __main__ - WARNING - [UPDATE] "None" causa del error "urllib3 HTTPError HTTPSConnectionPool(host='api.telegram.org', port=443): Max retries exceeded with url: /bot5019690287:AAH9nfL4sWzLiF5Tuza3Jf_DuqiFJZo8qqI/getUpdates (Caused by NewConnectionError('<telegram.vendor.ptb_urllib3.urllib3.connection.VerifiedHTTPSConnection object at 0x7f5dcc268220>: Failed to establish a new connection: [Errno -3] Temporary failure in name resolution'))"
2022-01-10 05:31:09,122 - telegram.vendor.ptb_urllib3.urllib3.connectionpool - WARNING - Retrying (Retry(total=2, connect=None, read=None, redirect=None)) after connection broken by 'NewConnectionError('<telegram.vendor.ptb_urllib3.urllib3.connection.VerifiedHTTPSConnection object at 0x7f5dcc21c580>: Failed to establish a new connection: [Errno -3] Temporary failure in name resolution')': /bot5019690287:AAH9nfL4sWzLiF5Tuza3Jf_DuqiFJZo8qqI/getUpdates
2022-01-10 05:31:09,123 - telegram.vendor.ptb_urllib3.urllib3.connectionpool - WARNING - Retrying (Retry(total=1, connect=None, read=None, redirect=None)) after connection broken by 'NewConnectionError('<telegram.vendor.ptb_urllib3.urllib3.connection.VerifiedHTTPSConnection object at 0x7f5dcc2682b0>: Failed to establish a new connection: [Errno -3] Temporary failure in name resolution')': /bot5019690287:AAH9nfL4sWzLiF5Tuza3Jf_DuqiFJZo8qqI/getUpdates
2022-01-10 05:31:09,124 - telegram.vendor.ptb_urllib3.urllib3.connectionpool - WARNING - Retrying (Retry(total=0, connect=None, read=None, redirect=None)) after connection broken by 'NewConnectionError('<telegram.vendor.ptb_urllib3.urllib3.connection.VerifiedHTTPSConnection object at 0x7f5dcc2684c0>: Failed to establish a new connection: [Errno -3] Temporary failure in name resolution')': /bot5019690287:AAH9nfL4sWzLiF5Tuza3Jf_DuqiFJZo8qqI/getUpdates
2022-01-10 05:31:09,126 - telegram.ext.updater - ERROR - Error while getting Updates: urllib3 HTTPError HTTPSConnectionPool(host='api.telegram.org', port=443): Max retries exceeded with url: /bot5019690287:AAH9nfL4sWzLiF5Tuza3Jf_DuqiFJZo8qqI/getUpdates (Caused by NewConnectionError('<telegram.vendor.ptb_urllib3.urllib3.connection.VerifiedHTTPSConnection object at 0x7f5dcc2689a0>: Failed to establish a new connection: [Errno -3] Temporary failure in name resolution'))
2022-01-10 05:31:09,126 - __main__ - WARNING - [UPDATE] "None" causa del error "urllib3 HTTPError HTTPSConnectionPool(host='api.telegram.org', port=443): Max retries exceeded with url: /bot5019690287:AAH9nfL4sWzLiF5Tuza3Jf_DuqiFJZo8qqI/getUpdates (Caused by NewConnectionError('<telegram.vendor.ptb_urllib3.urllib3.connection.VerifiedHTTPSConnection object at 0x7f5dcc2689a0>: Failed to establish a new connection: [Errno -3] Temporary failure in name resolution'))"
2022-01-10 05:31:10,630 - telegram.vendor.ptb_urllib3.urllib3.connectionpool - WARNING - Retrying (Retry(total=2, connect=None, read=None, redirect=None)) after connection broken by 'NewConnectionError('<telegram.vendor.ptb_urllib3.urllib3.connection.VerifiedHTTPSConnection object at 0x7f5dcc268220>: Failed to establish a new connection: [Errno -3] Temporary failure in name resolution')': /bot5019690287:AAH9nfL4sWzLiF5Tuza3Jf_DuqiFJZo8qqI/getUpdates
2022-01-10 05:31:10,632 - telegram.vendor.ptb_urllib3.urllib3.connectionpool - WARNING - Retrying (Retry(total=1, connect=None, read=None, redirect=None)) after connection broken by 'NewConnectionError('<telegram.vendor.ptb_urllib3.urllib3.connection.VerifiedHTTPSConnection object at 0x7f5dcc268f40>: Failed to establish a new connection: [Errno -3] Temporary failure in name resolution')': /bot5019690287:AAH9nfL4sWzLiF5Tuza3Jf_DuqiFJZo8qqI/getUpdates
2022-01-10 05:31:10,633 - telegram.vendor.ptb_urllib3.urllib3.connectionpool - WARNING - Retrying (Retry(total=0, connect=None, read=None, redirect=None)) after connection broken by 'NewConnectionError('<telegram.vendor.ptb_urllib3.urllib3.connection.VerifiedHTTPSConnection object at 0x7f5dcc268b50>: Failed to establish a new connection: [Errno -3] Temporary failure in name resolution')': /bot5019690287:AAH9nfL4sWzLiF5Tuza3Jf_DuqiFJZo8qqI/getUpdates
2022-01-10 05:31:10,636 - telegram.ext.updater - ERROR - Error while getting Updates: urllib3 HTTPError HTTPSConnectionPool(host='api.telegram.org', port=443): Max retries exceeded with url: /bot5019690287:AAH9nfL4sWzLiF5Tuza3Jf_DuqiFJZo8qqI/getUpdates (Caused by NewConnectionError('<telegram.vendor.ptb_urllib3.urllib3.connection.VerifiedHTTPSConnection object at 0x7f5dcdb04e50>: Failed to establish a new connection: [Errno -3] Temporary failure in name resolution'))
2022-01-10 05:31:10,636 - __main__ - WARNING - [UPDATE] "None" causa del error "urllib3 HTTPError HTTPSConnectionPool(host='api.telegram.org', port=443): Max retries exceeded with url: /bot5019690287:AAH9nfL4sWzLiF5Tuza3Jf_DuqiFJZo8qqI/getUpdates (Caused by NewConnectionError('<telegram.vendor.ptb_urllib3.urllib3.connection.VerifiedHTTPSConnection object at 0x7f5dcdb04e50>: Failed to establish a new connection: [Errno -3] Temporary failure in name resolution'))"
2022-01-10 05:31:29,932 - telegram.ext.updater - INFO - Received signal 15 (SIGTERM), stopping...
2022-01-10 05:31:29,958 - apscheduler.scheduler - INFO - Scheduler has been shut down
2022-04-04 15:35:53,436 - root - INFO - InfiniemBot Iniciado...
2022-04-04 15:35:53,439 - apscheduler.scheduler - INFO - Scheduler started
2022-04-04 15:35:55,103 - __main__ - INFO - [UPDATE] Usuario Max consume el servicio /suerte
2022-04-04 15:35:55,990 - __main__ - INFO - [UPDATE] Usuario Max consume el servicio /suerte
2022-04-04 15:35:56,401 - __main__ - INFO - [UPDATE] Usuario Max consume el servicio /suerte
2022-04-04 15:35:56,793 - __main__ - INFO - [UPDATE] Usuario Max consume el servicio /suerte
2022-04-04 15:35:57,175 - __main__ - INFO - [UPDATE] Usuario Max consume el servicio /suerte
2022-04-04 15:35:57,550 - __main__ - INFO - [UPDATE] Usuario Max consume el servicio /suerte
2022-04-04 15:35:57,921 - __main__ - INFO - [UPDATE] Usuario Max consume el servicio /acciones üí°
2022-04-04 15:35:58,331 - root - INFO - [NEW ACCESS] chat_id : 1211957358 - firstname : Max - lastname : None - username maxi_2022
2022-04-04 15:35:58,727 - root - INFO - [NEW ACCESS] chat_id : 1211957358 - firstname : Max - lastname : None - username maxi_2022
2022-04-04 15:35:59,104 - root - INFO - [NEW ACCESS] chat_id : 1211957358 - firstname : Max - lastname : None - username maxi_2022
2022-04-04 15:35:59,558 - root - INFO - [NEW ACCESS] chat_id : 1211957358 - firstname : Max - lastname : None - username maxi_2022
2022-04-04 15:35:59,968 - root - INFO - [NEW ACCESS] chat_id : 1211957358 - firstname : Max - lastname : None - username maxi_2022
2022-04-04 15:36:12,153 - root - INFO - [NEW ACCESS] chat_id : 1211957358 - firstname : Max - lastname : None - username maxi_2022
2022-04-04 15:36:28,958 - telegram.ext.updater - INFO - Received signal 2 (SIGINT), stopping...
2022-04-04 15:36:28,959 - apscheduler.scheduler - INFO - Scheduler has been shut down
2022-04-04 15:36:30,430 - telegram.ext.updater - WARNING - Exiting immediately!
